Workbook

Sheet Template
A1: Count | B1: Transaction Number | C1: Detail # | D1: Date | E1: Establishment Id | F1: Establishment | G1: Branch | H1: Payment Type | I1: Amount | J1: Account | K1: Quantity | L1: Unit Price | M1: Amount | N1: Total | O1: Item ID | P1: Brand | Q1: Type | R1: Details | S1: Notes
A2: =IF(OR(D2<>D1,D2=""),1,IF(NOT(AND(E2=E1,F2=F1,G2=G1)),A1+1,IF(OR(H2="",AND(H2<>"",H2<>H1,H1<>"")),A1,A1+1))) -> 1 | B2: =IF(D2<>"",TEXT(D2,"YYYYMMDD")&CHAR(64+A2),"") | C2: =IF(OR(B2="",B2<>B10),1,C10+1) -> 1 | F2: =INDEX(Establishment!B$2:B$1005,MATCH($E2,Establishment!$A$2:$A$1005,0)) -> #N/A | G2: =INDEX(Establishment!C$2:C$1005,MATCH($E2,Establishment!$A$2:$A$1005,0)) -> #N/A | M2: =K2*L2 -> 0 | N2: =IF(B2=B1,N1+M2,M2) -> 0 | P2: =INDEX(Items!B$2:B$1032,MATCH($O2,Items!$A$2:$A$1032,0)) -> #N/A | Q2: =INDEX(Items!C$2:C$1032,MATCH($O2,Items!$A$2:$A$1032,0)) -> #N/A | R2: =INDEX(Items!D$2:D$1032,MATCH($O2,Items!$A$2:$A$1032,0)) -> #N/A
A3: =IF(OR(D3<>D2,D3=""),1,IF(NOT(AND(E3=E2,F3=F2,G3=G2)),A2+1,IF(OR(H3="",AND(H3<>"",H3<>H2,H2<>"")),A2,A2+1))) -> 1 | B3: =IF(D3<>"",TEXT(D3,"YYYYMMDD")&CHAR(64+A3),"") | C3: =IF(OR(B3="",B3<>B11),1,C11+1) -> 1 | F3: =INDEX(Establishment!B$2:B$1005,MATCH($E3,Establishment!$A$2:$A$1005,0)) -> #N/A | G3: =INDEX(Establishment!C$2:C$1005,MATCH($E3,Establishment!$A$2:$A$1005,0)) -> #N/A | M3: =K3*L3 -> 0 | N3: =IF(B3=B2,N2+M3,M3) -> 0 | P3: =INDEX(Items!B$2:B$1032,MATCH($O3,Items!$A$2:$A$1032,0)) -> #N/A | Q3: =INDEX(Items!C$2:C$1032,MATCH($O3,Items!$A$2:$A$1032,0)) -> #N/A | R3: =INDEX(Items!D$2:D$1032,MATCH($O3,Items!$A$2:$A$1032,0)) -> #N/A
A4: =IF(OR(D4<>D3,D4=""),1,IF(NOT(AND(E4=E3,F4=F3,G4=G3)),A3+1,IF(OR(H4="",AND(H4<>"",H4<>H3,H3<>"")),A3,A3+1))) -> 1 | B4: =IF(D4<>"",TEXT(D4,"YYYYMMDD")&CHAR(64+A4),"") | C4: =IF(OR(B4="",B4<>B12),1,C12+1) -> 1 | F4: =INDEX(Establishment!B$2:B$1005,MATCH($E4,Establishment!$A$2:$A$1005,0)) -> #N/A | G4: =INDEX(Establishment!C$2:C$1005,MATCH($E4,Establishment!$A$2:$A$1005,0)) -> #N/A | M4: =K4*L4 -> 0 | N4: =IF(B4=B3,N3+M4,M4) -> 0 | P4: =INDEX(Items!B$2:B$1032,MATCH($O4,Items!$A$2:$A$1032,0)) -> #N/A | Q4: =INDEX(Items!C$2:C$1032,MATCH($O4,Items!$A$2:$A$1032,0)) -> #N/A | R4: =INDEX(Items!D$2:D$1032,MATCH($O4,Items!$A$2:$A$1032,0)) -> #N/A
A5: =IF(OR(D5<>D4,D5=""),1,IF(NOT(AND(E5=E4,F5=F4,G5=G4)),A4+1,IF(OR(H5="",AND(H5<>"",H5<>H4,H4<>"")),A4,A4+1))) -> 1 | B5: =IF(D5<>"",TEXT(D5,"YYYYMMDD")&CHAR(64+A5),"") | C5: =IF(OR(B5="",B5<>B13),1,C13+1) -> 1 | F5: =INDEX(Establishment!B$2:B$1005,MATCH($E5,Establishment!$A$2:$A$1005,0)) -> #N/A | G5: =INDEX(Establishment!C$2:C$1005,MATCH($E5,Establishment!$A$2:$A$1005,0)) -> #N/A | M5: =K5*L5 -> 0 | N5: =IF(B5=B4,N4+M5,M5) -> 0 | P5: =INDEX(Items!B$2:B$1032,MATCH($O5,Items!$A$2:$A$1032,0)) -> #N/A | Q5: =INDEX(Items!C$2:C$1032,MATCH($O5,Items!$A$2:$A$1032,0)) -> #N/A | R5: =INDEX(Items!D$2:D$1032,MATCH($O5,Items!$A$2:$A$1032,0)) -> #N/A
A6: =IF(OR(D6<>D5,D6=""),1,IF(NOT(AND(E6=E5,F6=F5,G6=G5)),A5+1,IF(OR(H6="",AND(H6<>"",H6<>H5,H5<>"")),A5,A5+1))) -> 1 | B6: =IF(D6<>"",TEXT(D6,"YYYYMMDD")&CHAR(64+A6),"") | C6: =IF(OR(B6="",B6<>B14),1,C14+1) -> 1 | F6: =INDEX(Establishment!B$2:B$1005,MATCH($E6,Establishment!$A$2:$A$1005,0)) -> #N/A | G6: =INDEX(Establishment!C$2:C$1005,MATCH($E6,Establishment!$A$2:$A$1005,0)) -> #N/A | M6: =K6*L6 -> 0 | N6: =IF(B6=B5,N5+M6,M6) -> 0 | P6: =INDEX(Items!B$2:B$1032,MATCH($O6,Items!$A$2:$A$1032,0)) -> #N/A | Q6: =INDEX(Items!C$2:C$1032,MATCH($O6,Items!$A$2:$A$1032,0)) -> #N/A | R6: =INDEX(Items!D$2:D$1032,MATCH($O6,Items!$A$2:$A$1032,0)) -> #N/A
A7: =IF(OR(D7<>D6,D7=""),1,IF(NOT(AND(E7=E6,F7=F6,G7=G6)),A6+1,IF(OR(H7="",AND(H7<>"",H7<>H6,H6<>"")),A6,A6+1))) -> 1 | B7: =IF(D7<>"",TEXT(D7,"YYYYMMDD")&CHAR(64+A7),"") | C7: =IF(OR(B7="",B7<>B15),1,C15+1) -> 1 | F7: =INDEX(Establishment!B$2:B$1005,MATCH($E7,Establishment!$A$2:$A$1005,0)) -> #N/A | G7: =INDEX(Establishment!C$2:C$1005,MATCH($E7,Establishment!$A$2:$A$1005,0)) -> #N/A | M7: =K7*L7 -> 0 | N7: =IF(B7=B6,N6+M7,M7) -> 0 | P7: =INDEX(Items!B$2:B$1032,MATCH($O7,Items!$A$2:$A$1032,0)) -> #N/A | Q7: =INDEX(Items!C$2:C$1032,MATCH($O7,Items!$A$2:$A$1032,0)) -> #N/A | R7: =INDEX(Items!D$2:D$1032,MATCH($O7,Items!$A$2:$A$1032,0)) -> #N/A
A8: =IF(OR(D8<>D7,D8=""),1,IF(NOT(AND(E8=E7,F8=F7,G8=G7)),A7+1,IF(OR(H8="",AND(H8<>"",H8<>H7,H7<>"")),A7,A7+1))) -> 1 | B8: =IF(D8<>"",TEXT(D8,"YYYYMMDD")&CHAR(64+A8),"") | C8: =IF(OR(B8="",B8<>B7),1,C7+1) -> 1 | F8: =INDEX(Establishment!B$2:B$1005,MATCH($E8,Establishment!$A$2:$A$1005,0)) -> #N/A | G8: =INDEX(Establishment!C$2:C$1005,MATCH($E8,Establishment!$A$2:$A$1005,0)) -> #N/A | M8: =K8*L8 -> 0 | N8: =IF(B8=B7,N7+M8,M8) -> 0 | P8: =INDEX(Items!B$2:B$1032,MATCH($O8,Items!$A$2:$A$1032,0)) -> #N/A | Q8: =INDEX(Items!C$2:C$1032,MATCH($O8,Items!$A$2:$A$1032,0)) -> #N/A | R8: =INDEX(Items!D$2:D$1032,MATCH($O8,Items!$A$2:$A$1032,0)) -> #N/A
A9: =IF(OR(D9<>D8,D9=""),1,IF(NOT(AND(E9=E8,F9=F8,G9=G8)),A8+1,IF(OR(H9="",AND(H9<>"",H9<>H8,H8<>"")),A8,A8+1))) -> 1 | B9: =IF(D9<>"",TEXT(D9,"YYYYMMDD")&CHAR(64+A9),"") | C9: =IF(OR(B9="",B9<>B8),1,C8+1) -> 1 | F9: =INDEX(Establishment!B$2:B$1005,MATCH($E9,Establishment!$A$2:$A$1005,0)) -> #N/A | G9: =INDEX(Establishment!C$2:C$1005,MATCH($E9,Establishment!$A$2:$A$1005,0)) -> #N/A | M9: =K9*L9 -> 0 | N9: =IF(B9=B8,N8+M9,M9) -> 0 | P9: =INDEX(Items!B$2:B$1032,MATCH($O9,Items!$A$2:$A$1032,0)) -> #N/A | Q9: =INDEX(Items!C$2:C$1032,MATCH($O9,Items!$A$2:$A$1032,0)) -> #N/A | R9: =INDEX(Items!D$2:D$1032,MATCH($O9,Items!$A$2:$A$1032,0)) -> #N/A
A10: =IF(OR(D10<>D9,D10=""),1,IF(NOT(AND(E10=E9,F10=F9,G10=G9)),A9+1,IF(OR(H10="",AND(H10<>"",H10<>H9,H9<>"")),A9,A9+1))) -> 1 | B10: =IF(D10<>"",TEXT(D10,"YYYYMMDD")&CHAR(64+A10),"") | C10: =IF(OR(B10="",B10<>B9),1,C9+1) -> 1 | F10: =INDEX(Establishment!B$2:B$1005,MATCH($E10,Establishment!$A$2:$A$1005,0)) -> #N/A | G10: =INDEX(Establishment!C$2:C$1005,MATCH($E10,Establishment!$A$2:$A$1005,0)) -> #N/A | M10: =K10*L10 -> 0 | N10: =IF(B10=B9,N9+M10,M10) -> 0 | P10: =INDEX(Items!B$2:B$1032,MATCH($O10,Items!$A$2:$A$1032,0)) -> #N/A | Q10: =INDEX(Items!C$2:C$1032,MATCH($O10,Items!$A$2:$A$1032,0)) -> #N/A | R10: =INDEX(Items!D$2:D$1032,MATCH($O10,Items!$A$2:$A$1032,0)) -> #N/A
A11: =IF(OR(D11<>D10,D11=""),1,IF(NOT(AND(E11=E10,F11=F10,G11=G10)),A10+1,IF(OR(H11="",AND(H11<>"",H11<>H10,H10<>"")),A10,A10+1))) -> 1 | B11: =IF(D11<>"",TEXT(D11,"YYYYMMDD")&CHAR(64+A11),"") | C11: =IF(OR(B11="",B11<>B10),1,C10+1) -> 1 | F11: =INDEX(Establishment!B$2:B$1005,MATCH($E11,Establishment!$A$2:$A$1005,0)) -> #N/A | G11: =INDEX(Establishment!C$2:C$1005,MATCH($E11,Establishment!$A$2:$A$1005,0)) -> #N/A | M11: =K11*L11 -> 0 | N11: =IF(B11=B10,N10+M11,M11) -> 0 | P11: =INDEX(Items!B$2:B$1032,MATCH($O11,Items!$A$2:$A$1032,0)) -> #N/A | Q11: =INDEX(Items!C$2:C$1032,MATCH($O11,Items!$A$2:$A$1032,0)) -> #N/A | R11: =INDEX(Items!D$2:D$1032,MATCH($O11,Items!$A$2:$A$1032,0)) -> #N/A
A12: =IF(OR(D12<>D11,D12=""),1,IF(NOT(AND(E12=E11,F12=F11,G12=G11)),A11+1,IF(OR(H12="",AND(H12<>"",H12<>H11,H11<>"")),A11,A11+1))) -> 1 | B12: =IF(D12<>"",TEXT(D12,"YYYYMMDD")&CHAR(64+A12),"") | C12: =IF(OR(B12="",B12<>B11),1,C11+1) -> 1 | F12: =INDEX(Establishment!B$2:B$1005,MATCH($E12,Establishment!$A$2:$A$1005,0)) -> #N/A | G12: =INDEX(Establishment!C$2:C$1005,MATCH($E12,Establishment!$A$2:$A$1005,0)) -> #N/A | M12: =K12*L12 -> 0 | N12: =IF(B12=B11,N11+M12,M12) -> 0 | P12: =INDEX(Items!B$2:B$1032,MATCH($O12,Items!$A$2:$A$1032,0)) -> #N/A | Q12: =INDEX(Items!C$2:C$1032,MATCH($O12,Items!$A$2:$A$1032,0)) -> #N/A | R12: =INDEX(Items!D$2:D$1032,MATCH($O12,Items!$A$2:$A$1032,0)) -> #N/A
A13: =IF(OR(D13<>D12,D13=""),1,IF(NOT(AND(E13=E12,F13=F12,G13=G12)),A12+1,IF(OR(H13="",AND(H13<>"",H13<>H12,H12<>"")),A12,A12+1))) -> 1 | B13: =IF(D13<>"",TEXT(D13,"YYYYMMDD")&CHAR(64+A13),"") | C13: =IF(OR(B13="",B13<>B12),1,C12+1) -> 1 | F13: =INDEX(Establishment!B$2:B$1005,MATCH($E13,Establishment!$A$2:$A$1005,0)) -> #N/A | G13: =INDEX(Establishment!C$2:C$1005,MATCH($E13,Establishment!$A$2:$A$1005,0)) -> #N/A | M13: =K13*L13 -> 0 | N13: =IF(B13=B12,N12+M13,M13) -> 0 | P13: =INDEX(Items!B$2:B$1032,MATCH($O13,Items!$A$2:$A$1032,0)) -> #N/A | Q13: =INDEX(Items!C$2:C$1032,MATCH($O13,Items!$A$2:$A$1032,0)) -> #N/A | R13: =INDEX(Items!D$2:D$1032,MATCH($O13,Items!$A$2:$A$1032,0)) -> #N/A
A14: =IF(OR(D14<>D13,D14=""),1,IF(NOT(AND(E14=E13,F14=F13,G14=G13)),A13+1,IF(OR(H14="",AND(H14<>"",H14<>H13,H13<>"")),A13,A13+1))) -> 1 | B14: =IF(D14<>"",TEXT(D14,"YYYYMMDD")&CHAR(64+A14),"") | C14: =IF(OR(B14="",B14<>B13),1,C13+1) -> 1 | F14: =INDEX(Establishment!B$2:B$1005,MATCH($E14,Establishment!$A$2:$A$1005,0)) -> #N/A | G14: =INDEX(Establishment!C$2:C$1005,MATCH($E14,Establishment!$A$2:$A$1005,0)) -> #N/A | M14: =K14*L14 -> 0 | N14: =IF(B14=B13,N13+M14,M14) -> 0 | P14: =INDEX(Items!B$2:B$1032,MATCH($O14,Items!$A$2:$A$1032,0)) -> #N/A | Q14: =INDEX(Items!C$2:C$1032,MATCH($O14,Items!$A$2:$A$1032,0)) -> #N/A | R14: =INDEX(Items!D$2:D$1032,MATCH($O14,Items!$A$2:$A$1032,0)) -> #N/A
A15: =IF(OR(D15<>D14,D15=""),1,IF(NOT(AND(E15=E14,F15=F14,G15=G14)),A14+1,IF(OR(H15="",AND(H15<>"",H15<>H14,H14<>"")),A14,A14+1))) -> 1 | B15: =IF(D15<>"",TEXT(D15,"YYYYMMDD")&CHAR(64+A15),"") | C15: =IF(OR(B15="",B15<>B14),1,C14+1) -> 1 | F15: =INDEX(Establishment!B$2:B$1005,MATCH($E15,Establishment!$A$2:$A$1005,0)) -> #N/A | G15: =INDEX(Establishment!C$2:C$1005,MATCH($E15,Establishment!$A$2:$A$1005,0)) -> #N/A | M15: =K15*L15 -> 0 | N15: =IF(B15=B14,N14+M15,M15) -> 0 | P15: =INDEX(Items!B$2:B$1032,MATCH($O15,Items!$A$2:$A$1032,0)) -> #N/A | Q15: =INDEX(Items!C$2:C$1032,MATCH($O15,Items!$A$2:$A$1032,0)) -> #N/A | R15: =INDEX(Items!D$2:D$1032,MATCH($O15,Items!$A$2:$A$1032,0)) -> #N/A
A16: =IF(OR(D16<>D15,D16=""),1,IF(NOT(AND(E16=E15,F16=F15,G16=G15)),A15+1,IF(OR(H16="",AND(H16<>"",H16<>H15,H15<>"")),A15,A15+1))) -> 1 | B16: =IF(D16<>"",TEXT(D16,"YYYYMMDD")&CHAR(64+A16),"") | C16: =IF(OR(B16="",B16<>B15),1,C15+1) -> 1 | F16: =INDEX(Establishment!B$2:B$1005,MATCH($E16,Establishment!$A$2:$A$1005,0)) -> #N/A | G16: =INDEX(Establishment!C$2:C$1005,MATCH($E16,Establishment!$A$2:$A$1005,0)) -> #N/A | M16: =K16*L16 -> 0 | N16: =IF(B16=B15,N15+M16,M16) -> 0 | P16: =INDEX(Items!B$2:B$1032,MATCH($O16,Items!$A$2:$A$1032,0)) -> #N/A | Q16: =INDEX(Items!C$2:C$1032,MATCH($O16,Items!$A$2:$A$1032,0)) -> #N/A | R16: =INDEX(Items!D$2:D$1032,MATCH($O16,Items!$A$2:$A$1032,0)) -> #N/A
A17: =IF(OR(D17<>D16,D17=""),1,IF(NOT(AND(E17=E16,F17=F16,G17=G16)),A16+1,IF(OR(H17="",AND(H17<>"",H17<>H16,H16<>"")),A16,A16+1))) -> 1 | B17: =IF(D17<>"",TEXT(D17,"YYYYMMDD")&CHAR(64+A17),"") | C17: =IF(OR(B17="",B17<>B16),1,C16+1) -> 1 | F17: =INDEX(Establishment!B$2:B$1005,MATCH($E17,Establishment!$A$2:$A$1005,0)) -> #N/A | G17: =INDEX(Establishment!C$2:C$1005,MATCH($E17,Establishment!$A$2:$A$1005,0)) -> #N/A | M17: =K17*L17 -> 0 | N17: =IF(B17=B16,N16+M17,M17) -> 0 | P17: =INDEX(Items!B$2:B$1032,MATCH($O17,Items!$A$2:$A$1032,0)) -> #N/A | Q17: =INDEX(Items!C$2:C$1032,MATCH($O17,Items!$A$2:$A$1032,0)) -> #N/A | R17: =INDEX(Items!D$2:D$1032,MATCH($O17,Items!$A$2:$A$1032,0)) -> #N/A
A18: =IF(OR(D18<>D17,D18=""),1,IF(NOT(AND(E18=E17,F18=F17,G18=G17)),A17+1,IF(OR(H18="",AND(H18<>"",H18<>H17,H17<>"")),A17,A17+1))) -> 1 | B18: =IF(D18<>"",TEXT(D18,"YYYYMMDD")&CHAR(64+A18),"") | C18: =IF(OR(B18="",B18<>B17),1,C17+1) -> 1 | F18: =INDEX(Establishment!B$2:B$1005,MATCH($E18,Establishment!$A$2:$A$1005,0)) -> #N/A | G18: =INDEX(Establishment!C$2:C$1005,MATCH($E18,Establishment!$A$2:$A$1005,0)) -> #N/A | M18: =K18*L18 -> 0 | N18: =IF(B18=B17,N17+M18,M18) -> 0 | P18: =INDEX(Items!B$2:B$1032,MATCH($O18,Items!$A$2:$A$1032,0)) -> #N/A | Q18: =INDEX(Items!C$2:C$1032,MATCH($O18,Items!$A$2:$A$1032,0)) -> #N/A | R18: =INDEX(Items!D$2:D$1032,MATCH($O18,Items!$A$2:$A$1032,0)) -> #N/A
A19: =IF(OR(D19<>D18,D19=""),1,IF(NOT(AND(E19=E18,F19=F18,G19=G18)),A18+1,IF(OR(H19="",AND(H19<>"",H19<>H18,H18<>"")),A18,A18+1))) -> 1 | B19: =IF(D19<>"",TEXT(D19,"YYYYMMDD")&CHAR(64+A19),"") | C19: =IF(OR(B19="",B19<>B18),1,C18+1) -> 1 | F19: =INDEX(Establishment!B$2:B$1005,MATCH($E19,Establishment!$A$2:$A$1005,0)) -> #N/A | G19: =INDEX(Establishment!C$2:C$1005,MATCH($E19,Establishment!$A$2:$A$1005,0)) -> #N/A | M19: =K19*L19 -> 0 | N19: =IF(B19=B18,N18+M19,M19) -> 0 | P19: =INDEX(Items!B$2:B$1032,MATCH($O19,Items!$A$2:$A$1032,0)) -> #N/A | Q19: =INDEX(Items!C$2:C$1032,MATCH($O19,Items!$A$2:$A$1032,0)) -> #N/A | R19: =INDEX(Items!D$2:D$1032,MATCH($O19,Items!$A$2:$A$1032,0)) -> #N/A
... A25: =IF(OR(D25<>D24,D25=""),1,IF(NOT(AND(E25=E24,F25=F24,G25=G24)),A24+1,IF(OR(H25="",AND(H25<>"",H25<>H24,H24<>"")),A24,A24+1))) -> 1 | B25: =IF(D25<>"",TEXT(D25,"YYYYMMDD")&CHAR(64+A25),"") | C25: =IF(OR(B25="",B25<>B24),1,C24+1) -> 1 | F25: =INDEX(Establishment!B$2:B$1005,MATCH($E25,Establishment!$A$2:$A$1005,0)) -> #N/A | G25: =INDEX(Establishment!C$2:C$1005,MATCH($E25,Establishment!$A$2:$A$1005,0)) -> #N/A | M25: =K25*L25 -> 0 | N25: =IF(B25=B24,N24+M25,M25) -> 0 | P25: =INDEX(Items!B$2:B$1032,MATCH($O25,Items!$A$2:$A$1032,0)) -> #N/A | Q25: =INDEX(Items!C$2:C$1032,MATCH($O25,Items!$A$2:$A$1032,0)) -> #N/A | R25: =INDEX(Items!D$2:D$1032,MATCH($O25,Items!$A$2:$A$1032,0)) -> #N/A
A26: =IF(OR(D26<>D25,D26=""),1,IF(NOT(AND(E26=E25,F26=F25,G26=G25)),A25+1,IF(OR(H26="",AND(H26<>"",H26<>H25,H25<>"")),A25,A25+1))) -> 1 | B26: =IF(D26<>"",TEXT(D26,"YYYYMMDD")&CHAR(64+A26),"") | C26: =IF(OR(B26="",B26<>B25),1,C25+1) -> 1 | F26: Street Vendor | G26: Fried Chicken Seller | M26: =K26*L26 -> 0 | N26: =IF(B26=B25,N25+M26,M26) -> 0 | P26: =INDEX(Items!B$2:B$1032,MATCH($O26,Items!$A$2:$A$1032,0)) -> #N/A | Q26: =INDEX(Items!C$2:C$1032,MATCH($O26,Items!$A$2:$A$1032,0)) -> #N/A | R26: =INDEX(Items!D$2:D$1032,MATCH($O26,Items!$A$2:$A$1032,0)) -> #N/A
A27: =IF(OR(D27<>D26,D27=""),1,IF(NOT(AND(E27=E26,F27=F26,G27=G26)),A26+1,IF(OR(H27="",AND(H27<>"",H27<>H26,H26<>"")),A26,A26+1))) -> 1 | B27: =IF(D27<>"",TEXT(D27,"YYYYMMDD")&CHAR(64+A27),"") | C27: =IF(OR(B27="",B27<>B26),1,C26+1) -> 1 | F27: Street Vendor | G27: Fried Chicken Seller | M27: =K27*L27 -> 0 | N27: =IF(B27=B26,N26+M27,M27) -> 0 | P27: =INDEX(Items!B$2:B$1032,MATCH($O27,Items!$A$2:$A$1032,0)) -> #N/A | Q27: =INDEX(Items!C$2:C$1032,MATCH($O27,Items!$A$2:$A$1032,0)) -> #N/A | R27: =INDEX(Items!D$2:D$1032,MATCH($O27,Items!$A$2:$A$1032,0)) -> #N/A
A28: =IF(OR(D28<>D27,D28=""),1,IF(NOT(AND(E28=E27,F28=F27,G28=G27)),A27+1,IF(OR(H28="",AND(H28<>"",H28<>H27,H27<>"")),A27,A27+1))) -> 1 | B28: =IF(D28<>"",TEXT(D28,"YYYYMMDD")&CHAR(64+A28),"") | C28: =IF(OR(B28="",B28<>B27),1,C27+1) -> 1 | F28: Street Vendor | G28: Fried Chicken Seller | M28: =K28*L28 -> 0 | N28: =IF(B28=B27,N27+M28,M28) -> 0 | P28: =INDEX(Items!B$2:B$1032,MATCH($O28,Items!$A$2:$A$1032,0)) -> #N/A | Q28: =INDEX(Items!C$2:C$1032,MATCH($O28,Items!$A$2:$A$1032,0)) -> #N/A | R28: =INDEX(Items!D$2:D$1032,MATCH($O28,Items!$A$2:$A$1032,0)) -> #N/A
A29: =IF(OR(D29<>D28,D29=""),1,IF(NOT(AND(E29=E28,F29=F28,G29=G28)),A28+1,IF(OR(H29="",AND(H29<>"",H29<>H28,H28<>"")),A28,A28+1))) -> 1 | B29: =IF(D29<>"",TEXT(D29,"YYYYMMDD")&CHAR(64+A29),"") | C29: =IF(OR(B29="",B29<>B28),1,C28+1) -> 1 | F29: =INDEX(Establishment!B$2:B$1005,MATCH($E29,Establishment!$A$2:$A$1005,0)) -> #N/A | G29: =INDEX(Establishment!C$2:C$1005,MATCH($E29,Establishment!$A$2:$A$1005,0)) -> #N/A | M29: =K29*L29 -> 0 | N29: =IF(B29=B28,N28+M29,M29) -> 0 | P29: =INDEX(Items!B$2:B$1032,MATCH($O29,Items!$A$2:$A$1032,0)) -> #N/A | Q29: =INDEX(Items!C$2:C$1032,MATCH($O29,Items!$A$2:$A$1032,0)) -> #N/A | R29: =INDEX(Items!D$2:D$1032,MATCH($O29,Items!$A$2:$A$1032,0)) -> #N/A
A30: =IF(OR(D30<>D29,D30=""),1,IF(NOT(AND(E30=E29,F30=F29,G30=G29)),A29+1,IF(OR(H30="",AND(H30<>"",H30<>H29,H29<>"")),A29,A29+1))) -> 1 | B30: =IF(D30<>"",TEXT(D30,"YYYYMMDD")&CHAR(64+A30),"") | C30: =IF(OR(B30="",B30<>B29),1,C29+1) -> 1 | F30: =INDEX(Establishment!B$2:B$1005,MATCH($E30,Establishment!$A$2:$A$1005,0)) -> #N/A | G30: =INDEX(Establishment!C$2:C$1005,MATCH($E30,Establishment!$A$2:$A$1005,0)) -> #N/A | M30: =K30*L30 -> 0 | N30: =IF(B30=B29,N29+M30,M30) -> 0 | P30: =INDEX(Items!B$2:B$1032,MATCH($O30,Items!$A$2:$A$1032,0)) -> #N/A | Q30: =INDEX(Items!C$2:C$1032,MATCH($O30,Items!$A$2:$A$1032,0)) -> #N/A | R30: =INDEX(Items!D$2:D$1032,MATCH($O30,Items!$A$2:$A$1032,0)) -> #N/A
A31: =IF(OR(D31<>D30,D31=""),1,IF(NOT(AND(E31=E30,F31=F30,G31=G30)),A30+1,IF(OR(H31="",AND(H31<>"",H31<>H30,H30<>"")),A30,A30+1))) -> 1 | B31: =IF(D31<>"",TEXT(D31,"YYYYMMDD")&CHAR(64+A31),"") | C31: =IF(OR(B31="",B31<>B30),1,C30+1) -> 1 | F31: =INDEX(Establishment!B$2:B$1005,MATCH($E31,Establishment!$A$2:$A$1005,0)) -> #N/A | G31: =INDEX(Establishment!C$2:C$1005,MATCH($E31,Establishment!$A$2:$A$1005,0)) -> #N/A | M31: =K31*L31 -> 0 | N31: =IF(B31=B30,N30+M31,M31) -> 0 | P31: =INDEX(Items!B$2:B$1032,MATCH($O31,Items!$A$2:$A$1032,0)) -> #N/A | Q31: =INDEX(Items!C$2:C$1032,MATCH($O31,Items!$A$2:$A$1032,0)) -> #N/A | R31: =INDEX(Items!D$2:D$1032,MATCH($O31,Items!$A$2:$A$1032,0)) -> #N/A
A32: =IF(OR(D32<>D31,D32=""),1,IF(NOT(AND(E32=E31,F32=F31,G32=G31)),A31+1,IF(OR(H32="",AND(H32<>"",H32<>H31,H31<>"")),A31,A31+1))) -> 1 | B32: =IF(D32<>"",TEXT(D32,"YYYYMMDD")&CHAR(64+A32),"") | C32: =IF(OR(B32="",B32<>B31),1,C31+1) -> 1 | F32: Street Vendor | G32: B. Rodriguez | M32: =K32*L32 -> 0 | N32: =IF(B32=B31,N31+M32,M32) -> 0 | P32: =INDEX(Items!B$2:B$1032,MATCH($O32,Items!$A$2:$A$1032,0)) -> #N/A | Q32: =INDEX(Items!C$2:C$1032,MATCH($O32,Items!$A$2:$A$1032,0)) -> #N/A | R32: =INDEX(Items!D$2:D$1032,MATCH($O32,Items!$A$2:$A$1032,0)) -> #N/A
A33: =IF(OR(D33<>D32,D33=""),1,IF(NOT(AND(E33=E32,F33=F32,G33=G32)),A32+1,IF(OR(H33="",AND(H33<>"",H33<>H32,H32<>"")),A32,A32+1))) -> 1 | B33: =IF(D33<>"",TEXT(D33,"YYYYMMDD")&CHAR(64+A33),"") | C33: =IF(OR(B33="",B33<>B32),1,C32+1) -> 1 | F33: Street Vendor | G33: B. Rodriguez | M33: =K33*L33 -> 0 | N33: =IF(B33=B32,N32+M33,M33) -> 0 | P33: =INDEX(Items!B$2:B$1032,MATCH($O33,Items!$A$2:$A$1032,0)) -> #N/A | Q33: =INDEX(Items!C$2:C$1032,MATCH($O33,Items!$A$2:$A$1032,0)) -> #N/A | R33: =INDEX(Items!D$2:D$1032,MATCH($O33,Items!$A$2:$A$1032,0)) -> #N/A
A34: =IF(OR(D34<>D33,D34=""),1,IF(NOT(AND(E34=E33,F34=F33,G34=G33)),A33+1,IF(OR(H34="",AND(H34<>"",H34<>H33,H33<>"")),A33,A33+1))) -> 1 | B34: =IF(D34<>"",TEXT(D34,"YYYYMMDD")&CHAR(64+A34),"") | C34: =IF(OR(B34="",B34<>B33),1,C33+1) -> 1 | F34: Street Vendor | G34: B. Rodriguez | M34: =K34*L34 -> 0 | N34: =IF(B34=B33,N33+M34,M34) -> 0 | P34: =INDEX(Items!B$2:B$1032,MATCH($O34,Items!$A$2:$A$1032,0)) -> #N/A | Q34: =INDEX(Items!C$2:C$1032,MATCH($O34,Items!$A$2:$A$1032,0)) -> #N/A | R34: =INDEX(Items!D$2:D$1032,MATCH($O34,Items!$A$2:$A$1032,0)) -> #N/A
A35: =IF(OR(D35<>D34,D35=""),1,IF(NOT(AND(E35=E34,F35=F34,G35=G34)),A34+1,IF(OR(H35="",AND(H35<>"",H35<>H34,H34<>"")),A34,A34+1))) -> 1 | B35: =IF(D35<>"",TEXT(D35,"YYYYMMDD")&CHAR(64+A35),"") | C35: =IF(OR(B35="",B35<>B34),1,C34+1) -> 1 | F35: Street Vendor | G35: B. Rodriguez | M35: =K35*L35 -> 0 | N35: =IF(B35=B34,N34+M35,M35) -> 0 | P35: =INDEX(Items!B$2:B$1032,MATCH($O35,Items!$A$2:$A$1032,0)) -> #N/A | Q35: =INDEX(Items!C$2:C$1032,MATCH($O35,Items!$A$2:$A$1032,0)) -> #N/A | R35: =INDEX(Items!D$2:D$1032,MATCH($O35,Items!$A$2:$A$1032,0)) -> #N/A
A36: =IF(OR(D36<>D35,D36=""),1,IF(NOT(AND(E36=E35,F36=F35,G36=G35)),A35+1,IF(OR(H36="",AND(H36<>"",H36<>H35,H35<>"")),A35,A35+1))) -> 1 | B36: =IF(D36<>"",TEXT(D36,"YYYYMMDD")&CHAR(64+A36),"") | C36: =IF(OR(B36="",B36<>B35),1,C35+1) -> 1 | F36: Carenderia | G36: B. Rodriguez | M36: =K36*L36 -> 0 | N36: =IF(B36=B35,N35+M36,M36) -> 0 | P36: =INDEX(Items!B$2:B$1032,MATCH($O36,Items!$A$2:$A$1032,0)) -> #N/A | Q36: =INDEX(Items!C$2:C$1032,MATCH($O36,Items!$A$2:$A$1032,0)) -> #N/A | R36: =INDEX(Items!D$2:D$1032,MATCH($O36,Items!$A$2:$A$1032,0)) -> #N/A
A37: =IF(OR(D37<>D36,D37=""),1,IF(NOT(AND(E37=E36,F37=F36,G37=G36)),A36+1,IF(OR(H37="",AND(H37<>"",H37<>H36,H36<>"")),A36,A36+1))) -> 1 | B37: =IF(D37<>"",TEXT(D37,"YYYYMMDD")&CHAR(64+A37),"") | C37: =IF(OR(B37="",B37<>B36),1,C36+1) -> 1 | F37: Carenderia | G37: B. Rodriguez | M37: =K37*L37 -> 0 | N37: =IF(B37=B36,N36+M37,M37) -> 0 | P37: =INDEX(Items!B$2:B$1032,MATCH($O37,Items!$A$2:$A$1032,0)) -> #N/A | Q37: =INDEX(Items!C$2:C$1032,MATCH($O37,Items!$A$2:$A$1032,0)) -> #N/A | R37: =INDEX(Items!D$2:D$1032,MATCH($O37,Items!$A$2:$A$1032,0)) -> #N/A
A38: =IF(OR(D38<>D37,D38=""),1,IF(NOT(AND(E38=E37,F38=F37,G38=G37)),A37+1,IF(OR(H38="",AND(H38<>"",H38<>H37,H37<>"")),A37,A37+1))) -> 1 | B38: =IF(D38<>"",TEXT(D38,"YYYYMMDD")&CHAR(64+A38),"") | C38: =IF(OR(B38="",B38<>B37),1,C37+1) -> 1 | F38: Carenderia | G38: B. Rodriguez | M38: =K38*L38 -> 0 | N38: =IF(B38=B37,N37+M38,M38) -> 0 | P38: =INDEX(Items!B$2:B$1032,MATCH($O38,Items!$A$2:$A$1032,0)) -> #N/A | Q38: =INDEX(Items!C$2:C$1032,MATCH($O38,Items!$A$2:$A$1032,0)) -> #N/A | R38: =INDEX(Items!D$2:D$1032,MATCH($O38,Items!$A$2:$A$1032,0)) -> #N/A
A39: =IF(OR(D39<>D38,D39=""),1,IF(NOT(AND(E39=E38,F39=F38,G39=G38)),A38+1,IF(OR(H39="",AND(H39<>"",H39<>H38,H38<>"")),A38,A38+1))) -> 1 | B39: =IF(D39<>"",TEXT(D39,"YYYYMMDD")&CHAR(64+A39),"") | C39: =IF(OR(B39="",B39<>B38),1,C38+1) -> 1 | F39: Carenderia | G39: B. Rodriguez | M39: =K39*L39 -> 0 | N39: =IF(B39=B38,N38+M39,M39) -> 0 | P39: =INDEX(Items!B$2:B$1032,MATCH($O39,Items!$A$2:$A$1032,0)) -> #N/A | Q39: =INDEX(Items!C$2:C$1032,MATCH($O39,Items!$A$2:$A$1032,0)) -> #N/A | R39: =INDEX(Items!D$2:D$1032,MATCH($O39,Items!$A$2:$A$1032,0)) -> #N/A
A40: =IF(OR(D40<>D39,D40=""),1,IF(NOT(AND(E40=E39,F40=F39,G40=G39)),A39+1,IF(OR(H40="",AND(H40<>"",H40<>H39,H39<>"")),A39,A39+1))) -> 1 | B40: =IF(D40<>"",TEXT(D40,"YYYYMMDD")&CHAR(64+A40),"") | C40: =IF(OR(B40="",B40<>B39),1,C39+1) -> 1 | F40: Carenderia | G40: B. Rodriguez | M40: =K40*L40 -> 0 | N40: =IF(B40=B39,N39+M40,M40) -> 0 | P40: =INDEX(Items!B$2:B$1032,MATCH($O40,Items!$A$2:$A$1032,0)) -> #N/A | Q40: =INDEX(Items!C$2:C$1032,MATCH($O40,Items!$A$2:$A$1032,0)) -> #N/A | R40: =INDEX(Items!D$2:D$1032,MATCH($O40,Items!$A$2:$A$1032,0)) -> #N/A
A41: =IF(OR(D41<>D40,D41=""),1,IF(NOT(AND(E41=E40,F41=F40,G41=G40)),A40+1,IF(OR(H41="",AND(H41<>"",H41<>H40,H40<>"")),A40,A40+1))) -> 1 | B41: =IF(D41<>"",TEXT(D41,"YYYYMMDD")&CHAR(64+A41),"") | C41: =IF(OR(B41="",B41<>B40),1,C40+1) -> 1 | F41: Carenderia | G41: B. Rodriguez | M41: =K41*L41 -> 0 | N41: =IF(B41=B40,N40+M41,M41) -> 0 | P41: =INDEX(Items!B$2:B$1032,MATCH($O41,Items!$A$2:$A$1032,0)) -> #N/A | Q41: =INDEX(Items!C$2:C$1032,MATCH($O41,Items!$A$2:$A$1032,0)) -> #N/A | R41: =INDEX(Items!D$2:D$1032,MATCH($O41,Items!$A$2:$A$1032,0)) -> #N/A
A42: =IF(OR(D42<>D41,D42=""),1,IF(NOT(AND(E42=E41,F42=F41,G42=G41)),A41+1,IF(OR(H42="",AND(H42<>"",H42<>H41,H41<>"")),A41,A41+1))) -> 1 | B42: =IF(D42<>"",TEXT(D42,"YYYYMMDD")&CHAR(64+A42),"") | C42: =IF(OR(B42="",B42<>B41),1,C41+1) -> 1 | F42: Carenderia | G42: B. Rodriguez | M42: =K42*L42 -> 0 | N42: =IF(B42=B41,N41+M42,M42) -> 0 | P42: =INDEX(Items!B$2:B$1032,MATCH($O42,Items!$A$2:$A$1032,0)) -> #N/A | Q42: =INDEX(Items!C$2:C$1032,MATCH($O42,Items!$A$2:$A$1032,0)) -> #N/A | R42: =INDEX(Items!D$2:D$1032,MATCH($O42,Items!$A$2:$A$1032,0)) -> #N/A
A43: =IF(OR(D43<>D42,D43=""),1,IF(NOT(AND(E43=E42,F43=F42,G43=G42)),A42+1,IF(OR(H43="",AND(H43<>"",H43<>H42,H42<>"")),A42,A42+1))) -> 1 | B43: =IF(D43<>"",TEXT(D43,"YYYYMMDD")&CHAR(64+A43),"") | C43: =IF(OR(B43="",B43<>B42),1,C42+1) -> 1 | F43: Carenderia | G43: B. Rodriguez | M43: =K43*L43 -> 0 | N43: =IF(B43=B42,N42+M43,M43) -> 0 | P43: =INDEX(Items!B$2:B$1032,MATCH($O43,Items!$A$2:$A$1032,0)) -> #N/A | Q43: =INDEX(Items!C$2:C$1032,MATCH($O43,Items!$A$2:$A$1032,0)) -> #N/A | R43: =INDEX(Items!D$2:D$1032,MATCH($O43,Items!$A$2:$A$1032,0)) -> #N/A
... A45: =IF(OR(D45<>D44,D45=""),1,IF(NOT(AND(E45=E44,F45=F44,G45=G44)),A44+1,IF(OR(H45="",AND(H45<>"",H45<>H44,H44<>"")),A44,A44+1))) -> 1 | B45: =IF(D45<>"",TEXT(D45,"YYYYMMDD")&CHAR(64+A45),"") | C45: =IF(OR(B45="",B45<>B44),1,C44+1) -> 1 | F45: Street Vendor | G45: Don Gil Garcia st. | M45: =K45*L45 -> 0 | N45: =IF(B45=B44,N44+M45,M45) -> 0 | P45: =INDEX(Items!B$2:B$1032,MATCH($O45,Items!$A$2:$A$1032,0)) -> #N/A | Q45: =INDEX(Items!C$2:C$1032,MATCH($O45,Items!$A$2:$A$1032,0)) -> #N/A | R45: =INDEX(Items!D$2:D$1032,MATCH($O45,Items!$A$2:$A$1032,0)) -> #N/A
A46: =IF(OR(D46<>D45,D46=""),1,IF(NOT(AND(E46=E45,F46=F45,G46=G45)),A45+1,IF(OR(H46="",AND(H46<>"",H46<>H45,H45<>"")),A45,A45+1))) -> 1 | B46: =IF(D46<>"",TEXT(D46,"YYYYMMDD")&CHAR(64+A46),"") | C46: =IF(OR(B46="",B46<>B45),1,C45+1) -> 1 | F46: =INDEX(Establishment!B$2:B$1005,MATCH($E46,Establishment!$A$2:$A$1005,0)) -> #N/A | G46: =INDEX(Establishment!C$2:C$1005,MATCH($E46,Establishment!$A$2:$A$1005,0)) -> #N/A | M46: =K46*L46 -> 0 | N46: =IF(B46=B45,N45+M46,M46) -> 0 | P46: =INDEX(Items!B$2:B$1032,MATCH($O46,Items!$A$2:$A$1032,0)) -> #N/A | Q46: =INDEX(Items!C$2:C$1032,MATCH($O46,Items!$A$2:$A$1032,0)) -> #N/A | R46: =INDEX(Items!D$2:D$1032,MATCH($O46,Items!$A$2:$A$1032,0)) -> #N/A
...

Sheet Misc
A1: Payment Type
A2: Cash
A3: MetroBank
A4: HSBC
A5: BPI Debit
A6: GC

Sheet Establishment
A1: ID | B1: Establishment | C1: Branch
A3: =B3&"-"&C3 -> One Time- | B3: One Time
A4: =B4&"-"&C4 -> 1st AutoGas-Panagdait | B4: 1st AutoGas | C4: Panagdait
A5: =B5&"-"&C5 -> A.N.G Cellshoppe-Colon Street | B5: A.N.G Cellshoppe | C5: Colon Street
A6: =B6&"-"&C6 -> Ace Hardware-SM City, Cebu | B6: Ace Hardware | C6: SM City, Cebu
A7: =B7&"-"&C7 -> Ace Hardware-SM Seaside, Cebu | B7: Ace Hardware | C7: SM Seaside, Cebu
A8: =B8&"-"&C8 -> Achi Ichiban-SM City, Cebu | B8: Achi Ichiban | C8: SM City, Cebu
A9: =B9&"-"&C9 -> Aircon Master-R. Landon street | B9: Aircon Master | C9: R. Landon street
A10: =B10&"-"&C10 -> Alberto's Pizza-Basak, Pardo | B10: Alberto's Pizza | C10: Basak, Pardo
A11: =B11&"-"&C11 -> Asian Homes Appliance-Osmenia Blvd. | B11: Asian Homes Appliance | C11: Osmenia Blvd.
A12: =B12&"-"&C12 -> Azian Thai Massage and SPA-Sancianko Street | B12: Azian Thai Massage and SPA | C12: Sancianko Street
A13: =B13&"-"&C13 -> Banana Stall-F. Llamas | B13: Banana Stall | C13: F. Llamas
A14: =B14&"-"&C14 -> Burger King-Panagdait | B14: Burger King | C14: Panagdait
A15: =B15&"-"&C15 -> Carenderia 14th Floor-ACC Tower Cebu Business Park | B15: Carenderia 14th Floor | C15: ACC Tower Cebu Business Park
... A34: =B34&"-"&C34 -> Colonnade-Colon Street | B34: Colonnade | C34: Colon Street
A35: =B35&"-"&C35 -> Crown Hardware- | B35: Crown Hardware
A36: =B36&"-"&C36 -> Delux Bakery-Magallanes | B36: Delux Bakery | C36: Magallanes
A37: =B37&"-"&C37 -> Department of Health-Vivente Sotto Memorial Medical Center | B37: Department of Health | C37: Vivente Sotto Memorial Medical Center
A38: =B38&"-"&C38 -> Diatoms-Katipunan | B38: Diatoms | C38: Katipunan
A39: =B39&"-"&C39 -> Dimsum Break-SM City, Cebu | B39: Dimsum Break | C39: SM City, Cebu
A40: =B40&"-"&C40 -> Domings-Guadalupe | B40: Domings | C40: Guadalupe
A41: =B41&"-"&C41 -> Dr. Edward Chua-Perpetuaql Hospital | B41: Dr. Edward Chua | C41: Perpetuaql Hospital
A42: =B42&"-"&C42 -> Dunkin Donuts-Ayala Center Cebu | B42: Dunkin Donuts | C42: Ayala Center Cebu
A43: =B43&"-"&C43 -> Dunkin Donuts-SM City, Cebu | B43: Dunkin Donuts | C43: SM City, Cebu
A44: =B44&"-"&C44 -> Dunkin Donuts-Super Metro (Basak San Nicolas) | B44: Dunkin Donuts | C44: Super Metro (Basak San Nicolas)
A45: =B45&"-"&C45 -> Echo Appliance Center-Magallanes | B45: Echo Appliance Center | C45: Magallanes
A46: =B46&"-"&C46 -> Egg Seller-C. Padilla (Mambaling) | B46: Egg Seller | C46: C. Padilla (Mambaling)
A47: =B47&"-"&C47 -> Eggcelsior-7Tsi - Guadalupe | B47: Eggcelsior | C47: 7Tsi - Guadalupe
... A73: =B73&"-"&C73 -> JOYOJoyo Marketing-SM Seaside, Cebu | B73: JOYOJoyo Marketing | C73: SM Seaside, Cebu
A74: =B74&"-"&C74 -> JPV-V. Rama Ave. | B74: JPV | C74: V. Rama Ave. | D74: at the back of Phoenix Gasoline Station
A75: =B75&"-"&C75 -> Julies Bakeshope-Basak San Nicolas | B75: Julies Bakeshope | C75: Basak San Nicolas
A76: =B76&"-"&C76 -> Julies Bakeshope-F. Llamas | B76: Julies Bakeshope | C76: F. Llamas
A77: =B77&"-"&C77 -> Julies Bakeshope-Junquera Ext | B77: Julies Bakeshope | C77: Junquera Ext
A78: =B78&"-"&C78 -> Julies Bakeshope-Tisa | B78: Julies Bakeshope | C78: Tisa
A79: =B79&"-"&C79 -> Julies Bakeshope-Urgello | B79: Julies Bakeshope | C79: Urgello
A80: =B80&"-"&C80 -> Kakeng-Parkmall | B80: Kakeng | C80: Parkmall
A81: =B81&"-"&C81 -> Kakeng-Plaridel | B81: Kakeng | C81: Plaridel
A82: =B82&"-"&C82 -> Kapitan AutoParts-Boromeo st. | B82: Kapitan AutoParts | C82: Boromeo st.
A83: =B83&"-"&C83 -> KFC-Panagdait | B83: KFC | C83: Panagdait
A84: =B84&"-"&C84 -> KFC-SM Seaside, Cebu | B84: KFC | C84: SM Seaside, Cebu
...

Sheet Accounts
A1: ID | B1: Type | C1: Account | D1: Detail
A2: =B2&"-"&C2&"-"&D2 -> Accessories-Zach-00000 | B2: Accessories | C2: Zach | D2: 00000
A3: =B3&"-"&C3&"-"&D3 -> Baking-00000-00000 | B3: Baking | C3: 00000 | D3: 00000
A4: =B4&"-"&C4&"-"&D4 -> Bonding-00000-Family | B4: Bonding | C4: 00000 | D4: Family
A5: =B5&"-"&C5&"-"&D5 -> Bonding-00001-Bedian | B5: Bonding | C5: 00001 | D5: Bedian
A6: =B6&"-"&C6&"-"&D6 -> Bonding-00002-Kids | B6: Bonding | C6: 00002 | D6: Kids
A7: =B7&"-"&C7&"-"&D7 -> Bonding-00003-Brayton | B7: Bonding | C7: 00003 | D7: Brayton
A8: =B8&"-"&C8&"-"&D8 -> Bonding-00004-Kaleb | B8: Bonding | C8: 00004 | D8: Kaleb
A9: =B9&"-"&C9&"-"&D9 -> Car-00000-Maintenance | B9: Car | C9: 00000 | D9: Maintenance
A10: =B10&"-"&C10&"-"&D10 -> Car-Avanza-Fuel | B10: Car | C10: Avanza | D10: Fuel
A11: =B11&"-"&C11&"-"&D11 -> Car-Avanza-Laundry | B11: Car | C11: Avanza | D11: Laundry
A12: =B12&"-"&C12&"-"&D12 -> Car-Avanza-Maintenance | B12: Car | C12: Avanza | D12: Maintenance
A13: =B13&"-"&C13&"-"&D13 -> Car-Avanza-Expense | B13: Car | C13: Avanza | D13: Expense
... A16: =B16&"-"&C16&"-"&D16 -> Car-Carens-Expense | B16: Car | C16: Carens | D16: Expense
A17: =B17&"-"&C17&"-"&D17 -> Car-Parking- | B17: Car | C17: Parking
A18: =B18&"-"&C18&"-"&D18 -> Celebration-Zach-00000 | B18: Celebration | C18: Zach | D18: 00000
A19: =B19&"-"&C19&"-"&D19 -> Cellphone-Kaleb-00000 | B19: Cellphone | C19: Kaleb | D19: 00000
A20: =B20&"-"&C20&"-"&D20 -> Cellphone-Bedian-00000 | B20: Cellphone | C20: Bedian | D20: 00000
A21: =B21&"-"&C21&"-"&D21 -> Cellphone-Brayton-00000 | B21: Cellphone | C21: Brayton | D21: 00000
A22: =B22&"-"&C22&"-"&D22 -> Cellphone-Zach-00000 | B22: Cellphone | C22: Zach | D22: 00000
A23: =B23&"-"&C23&"-"&D23 -> Clothing-Brayton-00000 | B23: Clothing | C23: Brayton | D23: 00000
A24: =B24&"-"&C24&"-"&D24 -> Clothing-Kaleb-00000 | B24: Clothing | C24: Kaleb | D24: 00000
A25: =B25&"-"&C25&"-"&D25 -> Computer-Twins-00000 | B25: Computer | C25: Twins | D25: 00000
A26: =B26&"-"&C26&"-"&D26 -> Computer-Bedian-00000 | B26: Computer | C26: Bedian | D26: 00000
A27: =B27&"-"&C27&"-"&D27 -> Computer-Brayton-00000 | B27: Computer | C27: Brayton | D27: 00000
A28: =B28&"-"&C28&"-"&D28 -> Computer-Kaleb-00000 | B28: Computer | C28: Kaleb | D28: 00000
A29: =B29&"-"&C29&"-"&D29 -> Computer-Oldhouse-00000 | B29: Computer | C29: Oldhouse | D29: 00000
... A45: =B45&"-"&C45&"-"&D45 -> Expense-Shirley-00000 | B45: Expense | C45: Shirley | D45: 00000
A46: =B46&"-"&C46&"-"&D46 -> Expense-Keng Offering- | B46: Expense | C46: Keng Offering
A47: Expense-Mama's Offering | B47: Expense | C47: Mama's Offering
A48: =B48&"-"&C48&"-"&D48 -> Expense-Parent's Offering- | B48: Expense | C48: Parent's Offering
A49: =B49&"-"&C49&"-"&D49 -> Expense-Bedian-0000 | B49: Expense | C49: Bedian | D49: 0000
A50: =B50&"-"&C50&"-"&D50 -> Expense-Zach-0000 | B50: Expense | C50: Zach | D50: 0000
A51: =B51&"-"&C51&"-"&D51 -> Expense-Shipping and Delivery-0000 | B51: Expense | C51: Shipping and Delivery | D51: 0000
A52: =B52&"-"&C52&"-"&D52 -> Gift-Twins-00000 | B52: Gift | C52: Twins | D52: 00000
A53: =B53&"-"&C53&"-"&D53 -> Gift-Bedian-00000 | B53: Gift | C53: Bedian | D53: 00000
A54: =B54&"-"&C54&"-"&D54 -> Gift-Brayton-00000 | B54: Gift | C54: Brayton | D54: 00000
A55: =B55&"-"&C55&"-"&D55 -> Gift-Others-00000 | B55: Gift | C55: Others | D55: 00000
A56: =B56&"-"&C56&"-"&D56 -> Gift-Kaleb-00000 | B56: Gift | C56: Kaleb | D56: 00000
A57: =B57&"-"&C57&"-"&D57 -> Grocery-00000-00000 | B57: Grocery | C57: 00000 | D57: 00000
...

Sheet Items
A1: ID | B1: Brand | C1: Type | D1: Details | E1: Category
E2: Category | G2: 0. One Time only
E3: Category | G3: 1. Medicine
E4: Category | G4: 2. Food and Drinks
E5: Category | G5: 4. Snacks
E6: Category | G6: 5. Automotive
E7: Category | G7: 6. Service
E8: Category | G8: 7. Household
E9: Category | G9: 8. Religious
E10: Category | G10: 9. Discount and Tips
E11: Category | G11: 10. Appliance
E12: Category
A13: =C13&IF(B13<>"","("&B13&") "," ")&D13 -> Unliquidated(Items) | B13: Items | C13: Unliquidated
A14: One Time | C14: One Time | E14: 0. One Time only
A15: =C15&IF(B15<>"","("&B15&") "," ")&D15 -> (Omega) 120ml | B15: Omega | D15: 120ml | E15: 1. Medicine
A16: =C16&IF(B16<>"","("&B16&") "," ")&D16 -> (Omega) 60ml | B16: Omega | D16: 60ml | E16: 1. Medicine
A17: =C17&IF(B17<>"","("&B17&") "," ")&D17 -> (Rosuvastatin) 5mg | B17: Rosuvastatin | D17: 5mg | E17: 1. Medicine
A18: =C18&IF(B18<>"","("&B18&") "," ")&D18 -> Acetylcysteine (Fluimucil) 100mg | B18: Fluimucil | C18: Acetylcysteine | D18: 100mg | E18: 1. Medicine
A19: =C19&IF(B19<>"","("&B19&") "," ")&D19 -> Aldactone(Spironolactone) 25mg | B19: Spironolactone | C19: Aldactone | D19: 25mg | E19: 1. Medicine
A20: Aldactone(Spironolactone) 50mg | B20: Spironolactone | C20: Aldactone | D20: 50mg | E20: 1. Medicine
A21: Amlodipine(Rite-Med) 5mg | B21: Rite-Med | C21: Amlodipine | D21: 5mg | E21: 1. Medicine
A22: =C22&IF(B22<>"","("&B22&") "," ")&D22 -> Antasid(Maalox) | B22: Maalox | C22: Antasid | E22: 1. Medicine
A23: =C23&IF(B23<>"","("&B23&") "," ")&D23 -> Ascorbic Acid(Rhea ) 500mg | B23: Rhea | C23: Ascorbic Acid | D23: 500mg | E23: 1. Medicine
A24: =C24&IF(B24<>"","("&B24&") "," ")&D24 -> Aspirin(Aspilets) 80mg | B24: Aspilets | C24: Aspirin | D24: 80mg | E24: 1. Medicine
A25: =C25&IF(B25<>"","("&B25&") "," ")&D25 -> AZITHROMYCIN Dihydrate(Zithromax) 15ml | B25: Zithromax | C25: AZITHROMYCIN Dihydrate | D25: 15ml | E25: 1. Medicine
A26: =C26&IF(B26<>"","("&B26&") "," ")&D26 -> AZITHROMYCIN Dihydrate(Zithromax) 22.5ml | B26: Zithromax | C26: AZITHROMYCIN Dihydrate | D26: 22.5ml | E26: 1. Medicine
A27: =C27&IF(B27<>"","("&B27&") "," ")&D27 -> Bilaxten(Bilastine) 20mg | B27: Bilastine | C27: Bilaxten | D27: 20mg | E27: 1. Medicine
A28: =C28&IF(B28<>"","("&B28&") "," ")&D28 -> Butamirate Forte(Sinecod) 50mg | B28: Sinecod | C28: Butamirate Forte | D28: 50mg | E28: 1. Medicine
A29: Carvedilol(BetaCard) 25mg | B29: BetaCard | C29: Carvedilol | D29: 25mg | E29: 1. Medicine
A30: Carvedilol(Cardipres) 25mg | B30: Cardipres | C30: Carvedilol | D30: 25mg | E30: 1. Medicine
A31: Carvid(Carvedilol) 25mg | B31: Carvedilol | C31: Carvid | D31: 25mg | E31: 1. Medicine
A32: =C32&IF(B32<>"","("&B32&") "," ")&D32 -> Cetirizine HCL(Rose Pharmacy) 10mg | B32: Rose Pharmacy | C32: Cetirizine HCL | D32: 10mg | E32: 1. Medicine
A33: =C33&IF(B33<>"","("&B33&") "," ")&D33 -> Clonidine HC1(Clonipress) 75mcg | B33: Clonipress | C33: Clonidine HC1 | D33: 75mcg | E33: 1. Medicine
A34: Clopidogrel(PLAZ) 175mg | B34: PLAZ | C34: Clopidogrel | D34: 175mg | E34: 1. Medicine
A35: Clopidogrel(Rhea) 175mg | B35: Rhea | C35: Clopidogrel | D35: 175mg | E35: 1. Medicine
A36: dapagliflozin(ForXiga) 10mg | B36: ForXiga | C36: dapagliflozin | D36: 10mg | E36: 1. Medicine
A37: =C37&IF(B37<>"","("&B37&") "," ")&D37 -> dapagliflozin/Metformin HCl(xigduo) 10mg/1000mg Tablet | B37: xigduo | C37: dapagliflozin/Metformin HCl | D37: 10mg/1000mg Tablet | E37: 1. Medicine
A38: Diamicron(Gliclazide ) 60mg | B38: Gliclazide | C38: Diamicron | D38: 60mg | E38: 1. Medicine
A39: =C39&IF(B39<>"","("&B39&") "," ")&D39 -> Doxofylline(Ansimar) 100mg/5ml | B39: Ansimar | C39: Doxofylline | D39: 100mg/5ml | E39: 1. Medicine
A40: =C40&IF(B40<>"","("&B40&") "," ")&D40 -> Energen(Chocolate) 8x30x40g | B40: Chocolate | C40: Energen | D40: 8x30x40g | E40: 1. Medicine
...

Sheet Sheet1
A1: 26.698 | B1: =A1 -> 26.698 | C1: =B1 -> 26.698 | D1: =B1 -> 26.698 | F1: 26.698
A2: 24.469 | B2: =A2 -> 24.469 | C2: =B2 -> 24.469 | E2: 24.469
A3: 23.583 | B3: =A3 -> 23.583 | C3: =B3 -> 23.583 | E3: 23.583
A4: 20 | B4: =A4 -> 20 | C4: =B4 -> 20
A5: 18.487 | B5: =A5 -> 18.487 | C5: 9 | D5: =B5 -> 18.487 | F5: 18.487
A6: 13.523 | B6: =A6 -> 13.523 | C6: =B6 -> 13.523 | D6: =B6 -> 13.523
A7: 2.727 | B7: =A7 -> 2.727 | C7: =B7 -> 2.727 | D7: =B7 -> 2.727 | F7: 2.727
A8: =SUM(A1:A7) -> 129.487 | B8: =SUM(B1:B7) -> 129.487 | C8: =SUM(C1:C7) -> 120 | D8: =SUM(D1:D7) -> 61.435 | E8: =SUM(E1:E7) -> 48.052 | F8: =SUM(F1:F7) -> 47.912
C9: =C8-120 -> 0 | D9: =D8-60 -> 1.435 | E9: =E8-60 -> -11.948 | F9: =F8-60 -> -12.088
C10: =57*C9 -> 0 | E10: =57*E9 -> -681.036 | F10: =57*F9 -> -689.016

Sheet 2023-01
A1: Count | B1: Transaction Number | C1: Detail # | D1: Date | E1: Establishment Id | F1: Establishment | G1: Branch | H1: Payment Type | I1: Amount | J1: Account | K1: Quantity | L1: Unit Price | M1: Amount | N1: Total | O1: Item ID | P1: Brand | Q1: Type | R1: Details | S1: Notes
A2: =IF(OR(D2<>D1,D2=""),1,IF(NOT(AND(E2=E1,F2=F1,G2=G1)),A1+1,IF(OR(H2="",AND(H2<>"",H2<>H1,H1<>"")),A1,A1+1))) -> 1 | B2: =IF(D2<>"",TEXT(D2,"YYYYMMDD")&CHAR(64+A2),"") | C2: =IF(OR(B2="",B2<>B10),1,C10+1) -> 1 | F2: =INDEX(Establishment!B$2:B$1005,MATCH($E2,Establishment!$A$2:$A$1005,0)) -> #N/A | G2: =INDEX(Establishment!C$2:C$1005,MATCH($E2,Establishment!$A$2:$A$1005,0)) -> #N/A | M2: =K2*L2 -> 0 | N2: =IF(B2=B1,N1+M2,M2) -> 0 | P2: =INDEX(Items!B$2:B$1032,MATCH($O2,Items!$A$2:$A$1032,0)) -> #N/A | Q2: =INDEX(Items!C$2:C$1032,MATCH($O2,Items!$A$2:$A$1032,0)) -> #N/A | R2: =INDEX(Items!D$2:D$1032,MATCH($O2,Items!$A$2:$A$1032,0)) -> #N/A
A3: =IF(OR(D3<>D2,D3=""),1,IF(NOT(AND(E3=E2,F3=F2,G3=G2)),A2+1,IF(OR(H3="",AND(H3<>"",H3<>H2,H2<>"")),A2,A2+1))) -> 1 | B3: =IF(D3<>"",TEXT(D3,"YYYYMMDD")&CHAR(64+A3),"") | C3: =IF(OR(B3="",B3<>B11),1,C11+1) -> 1 | F3: =INDEX(Establishment!B$2:B$1005,MATCH($E3,Establishment!$A$2:$A$1005,0)) -> #N/A | G3: =INDEX(Establishment!C$2:C$1005,MATCH($E3,Establishment!$A$2:$A$1005,0)) -> #N/A | M3: =K3*L3 -> 0 | N3: =IF(B3=B2,N2+M3,M3) -> 0 | P3: =INDEX(Items!B$2:B$1032,MATCH($O3,Items!$A$2:$A$1032,0)) -> #N/A | Q3: =INDEX(Items!C$2:C$1032,MATCH($O3,Items!$A$2:$A$1032,0)) -> #N/A | R3: =INDEX(Items!D$2:D$1032,MATCH($O3,Items!$A$2:$A$1032,0)) -> #N/A
A4: =IF(OR(D4<>D3,D4=""),1,IF(NOT(AND(E4=E3,F4=F3,G4=G3)),A3+1,IF(OR(H4="",AND(H4<>"",H4<>H3,H3<>"")),A3,A3+1))) -> 1 | B4: =IF(D4<>"",TEXT(D4,"YYYYMMDD")&CHAR(64+A4),"") | C4: =IF(OR(B4="",B4<>B12),1,C12+1) -> 1 | F4: =INDEX(Establishment!B$2:B$1005,MATCH($E4,Establishment!$A$2:$A$1005,0)) -> #N/A | G4: =INDEX(Establishment!C$2:C$1005,MATCH($E4,Establishment!$A$2:$A$1005,0)) -> #N/A | M4: =K4*L4 -> 0 | N4: =IF(B4=B3,N3+M4,M4) -> 0 | P4: =INDEX(Items!B$2:B$1032,MATCH($O4,Items!$A$2:$A$1032,0)) -> #N/A | Q4: =INDEX(Items!C$2:C$1032,MATCH($O4,Items!$A$2:$A$1032,0)) -> #N/A | R4: =INDEX(Items!D$2:D$1032,MATCH($O4,Items!$A$2:$A$1032,0)) -> #N/A
A5: =IF(OR(D5<>D4,D5=""),1,IF(NOT(AND(E5=E4,F5=F4,G5=G4)),A4+1,IF(OR(H5="",AND(H5<>"",H5<>H4,H4<>"")),A4,A4+1))) -> 1 | B5: =IF(D5<>"",TEXT(D5,"YYYYMMDD")&CHAR(64+A5),"") | C5: =IF(OR(B5="",B5<>B13),1,C13+1) -> 1 | F5: =INDEX(Establishment!B$2:B$1005,MATCH($E5,Establishment!$A$2:$A$1005,0)) -> #N/A | G5: =INDEX(Establishment!C$2:C$1005,MATCH($E5,Establishment!$A$2:$A$1005,0)) -> #N/A | M5: =K5*L5 -> 0 | N5: =IF(B5=B4,N4+M5,M5) -> 0 | P5: =INDEX(Items!B$2:B$1032,MATCH($O5,Items!$A$2:$A$1032,0)) -> #N/A | Q5: =INDEX(Items!C$2:C$1032,MATCH($O5,Items!$A$2:$A$1032,0)) -> #N/A | R5: =INDEX(Items!D$2:D$1032,MATCH($O5,Items!$A$2:$A$1032,0)) -> #N/A
A6: =IF(OR(D6<>D5,D6=""),1,IF(NOT(AND(E6=E5,F6=F5,G6=G5)),A5+1,IF(OR(H6="",AND(H6<>"",H6<>H5,H5<>"")),A5,A5+1))) -> 1 | B6: =IF(D6<>"",TEXT(D6,"YYYYMMDD")&CHAR(64+A6),"") | C6: =IF(OR(B6="",B6<>B14),1,C14+1) -> 1 | F6: =INDEX(Establishment!B$2:B$1005,MATCH($E6,Establishment!$A$2:$A$1005,0)) -> #N/A | G6: =INDEX(Establishment!C$2:C$1005,MATCH($E6,Establishment!$A$2:$A$1005,0)) -> #N/A | M6: =K6*L6 -> 0 | N6: =IF(B6=B5,N5+M6,M6) -> 0 | P6: =INDEX(Items!B$2:B$1032,MATCH($O6,Items!$A$2:$A$1032,0)) -> #N/A | Q6: =INDEX(Items!C$2:C$1032,MATCH($O6,Items!$A$2:$A$1032,0)) -> #N/A | R6: =INDEX(Items!D$2:D$1032,MATCH($O6,Items!$A$2:$A$1032,0)) -> #N/A
A7: =IF(OR(D7<>D6,D7=""),1,IF(NOT(AND(E7=E6,F7=F6,G7=G6)),A6+1,IF(OR(H7="",AND(H7<>"",H7<>H6,H6<>"")),A6,A6+1))) -> 1 | B7: =IF(D7<>"",TEXT(D7,"YYYYMMDD")&CHAR(64+A7),"") | C7: =IF(OR(B7="",B7<>B15),1,C15+1) -> 1 | F7: =INDEX(Establishment!B$2:B$1005,MATCH($E7,Establishment!$A$2:$A$1005,0)) -> #N/A | G7: =INDEX(Establishment!C$2:C$1005,MATCH($E7,Establishment!$A$2:$A$1005,0)) -> #N/A | M7: =K7*L7 -> 0 | N7: =IF(B7=B6,N6+M7,M7) -> 0 | P7: =INDEX(Items!B$2:B$1032,MATCH($O7,Items!$A$2:$A$1032,0)) -> #N/A | Q7: =INDEX(Items!C$2:C$1032,MATCH($O7,Items!$A$2:$A$1032,0)) -> #N/A | R7: =INDEX(Items!D$2:D$1032,MATCH($O7,Items!$A$2:$A$1032,0)) -> #N/A
A8: =IF(OR(D8<>D7,D8=""),1,IF(NOT(AND(E8=E7,F8=F7,G8=G7)),A7+1,IF(OR(H8="",AND(H8<>"",H8<>H7,H7<>"")),A7,A7+1))) -> 1 | B8: =IF(D8<>"",TEXT(D8,"YYYYMMDD")&CHAR(64+A8),"") | C8: =IF(OR(B8="",B8<>B7),1,C7+1) -> 1 | F8: =INDEX(Establishment!B$2:B$1005,MATCH($E8,Establishment!$A$2:$A$1005,0)) -> #N/A | G8: =INDEX(Establishment!C$2:C$1005,MATCH($E8,Establishment!$A$2:$A$1005,0)) -> #N/A | M8: =K8*L8 -> 0 | N8: =IF(B8=B7,N7+M8,M8) -> 0 | P8: =INDEX(Items!B$2:B$1032,MATCH($O8,Items!$A$2:$A$1032,0)) -> #N/A | Q8: =INDEX(Items!C$2:C$1032,MATCH($O8,Items!$A$2:$A$1032,0)) -> #N/A | R8: =INDEX(Items!D$2:D$1032,MATCH($O8,Items!$A$2:$A$1032,0)) -> #N/A
A9: =IF(OR(D9<>D8,D9=""),1,IF(NOT(AND(E9=E8,F9=F8,G9=G8)),A8+1,IF(OR(H9="",AND(H9<>"",H9<>H8,H8<>"")),A8,A8+1))) -> 1 | B9: =IF(D9<>"",TEXT(D9,"YYYYMMDD")&CHAR(64+A9),"") | C9: =IF(OR(B9="",B9<>B8),1,C8+1) -> 1 | F9: =INDEX(Establishment!B$2:B$1005,MATCH($E9,Establishment!$A$2:$A$1005,0)) -> #N/A | G9: =INDEX(Establishment!C$2:C$1005,MATCH($E9,Establishment!$A$2:$A$1005,0)) -> #N/A | M9: =K9*L9 -> 0 | N9: =IF(B9=B8,N8+M9,M9) -> 0 | P9: =INDEX(Items!B$2:B$1032,MATCH($O9,Items!$A$2:$A$1032,0)) -> #N/A | Q9: =INDEX(Items!C$2:C$1032,MATCH($O9,Items!$A$2:$A$1032,0)) -> #N/A | R9: =INDEX(Items!D$2:D$1032,MATCH($O9,Items!$A$2:$A$1032,0)) -> #N/A
A10: =IF(OR(D10<>D9,D10=""),1,IF(NOT(AND(E10=E9,F10=F9,G10=G9)),A9+1,IF(OR(H10="",AND(H10<>"",H10<>H9,H9<>"")),A9,A9+1))) -> 1 | B10: =IF(D10<>"",TEXT(D10,"YYYYMMDD")&CHAR(64+A10),"") | C10: =IF(OR(B10="",B10<>B9),1,C9+1) -> 1 | F10: =INDEX(Establishment!B$2:B$1005,MATCH($E10,Establishment!$A$2:$A$1005,0)) -> #N/A | G10: =INDEX(Establishment!C$2:C$1005,MATCH($E10,Establishment!$A$2:$A$1005,0)) -> #N/A | M10: =K10*L10 -> 0 | N10: =IF(B10=B9,N9+M10,M10) -> 0 | P10: =INDEX(Items!B$2:B$1032,MATCH($O10,Items!$A$2:$A$1032,0)) -> #N/A | Q10: =INDEX(Items!C$2:C$1032,MATCH($O10,Items!$A$2:$A$1032,0)) -> #N/A | R10: =INDEX(Items!D$2:D$1032,MATCH($O10,Items!$A$2:$A$1032,0)) -> #N/A
A11: =IF(OR(D11<>D10,D11=""),1,IF(NOT(AND(E11=E10,F11=F10,G11=G10)),A10+1,IF(OR(H11="",AND(H11<>"",H11<>H10,H10<>"")),A10,A10+1))) -> 1 | B11: =IF(D11<>"",TEXT(D11,"YYYYMMDD")&CHAR(64+A11),"") | C11: =IF(OR(B11="",B11<>B10),1,C10+1) -> 1 | F11: =INDEX(Establishment!B$2:B$1005,MATCH($E11,Establishment!$A$2:$A$1005,0)) -> #N/A | G11: =INDEX(Establishment!C$2:C$1005,MATCH($E11,Establishment!$A$2:$A$1005,0)) -> #N/A | M11: =K11*L11 -> 0 | N11: =IF(B11=B10,N10+M11,M11) -> 0 | P11: =INDEX(Items!B$2:B$1032,MATCH($O11,Items!$A$2:$A$1032,0)) -> #N/A | Q11: =INDEX(Items!C$2:C$1032,MATCH($O11,Items!$A$2:$A$1032,0)) -> #N/A | R11: =INDEX(Items!D$2:D$1032,MATCH($O11,Items!$A$2:$A$1032,0)) -> #N/A
A12: =IF(OR(D12<>D11,D12=""),1,IF(NOT(AND(E12=E11,F12=F11,G12=G11)),A11+1,IF(OR(H12="",AND(H12<>"",H12<>H11,H11<>"")),A11,A11+1))) -> 1 | B12: =IF(D12<>"",TEXT(D12,"YYYYMMDD")&CHAR(64+A12),"") | C12: =IF(OR(B12="",B12<>B11),1,C11+1) -> 1 | F12: =INDEX(Establishment!B$2:B$1005,MATCH($E12,Establishment!$A$2:$A$1005,0)) -> #N/A | G12: =INDEX(Establishment!C$2:C$1005,MATCH($E12,Establishment!$A$2:$A$1005,0)) -> #N/A | M12: =K12*L12 -> 0 | N12: =IF(B12=B11,N11+M12,M12) -> 0 | P12: =INDEX(Items!B$2:B$1032,MATCH($O12,Items!$A$2:$A$1032,0)) -> #N/A | Q12: =INDEX(Items!C$2:C$1032,MATCH($O12,Items!$A$2:$A$1032,0)) -> #N/A | R12: =INDEX(Items!D$2:D$1032,MATCH($O12,Items!$A$2:$A$1032,0)) -> #N/A
A13: =IF(OR(D13<>D12,D13=""),1,IF(NOT(AND(E13=E12,F13=F12,G13=G12)),A12+1,IF(OR(H13="",AND(H13<>"",H13<>H12,H12<>"")),A12,A12+1))) -> 1 | B13: =IF(D13<>"",TEXT(D13,"YYYYMMDD")&CHAR(64+A13),"") | C13: =IF(OR(B13="",B13<>B12),1,C12+1) -> 1 | F13: =INDEX(Establishment!B$2:B$1005,MATCH($E13,Establishment!$A$2:$A$1005,0)) -> #N/A | G13: =INDEX(Establishment!C$2:C$1005,MATCH($E13,Establishment!$A$2:$A$1005,0)) -> #N/A | M13: =K13*L13 -> 0 | N13: =IF(B13=B12,N12+M13,M13) -> 0 | P13: =INDEX(Items!B$2:B$1032,MATCH($O13,Items!$A$2:$A$1032,0)) -> #N/A | Q13: =INDEX(Items!C$2:C$1032,MATCH($O13,Items!$A$2:$A$1032,0)) -> #N/A | R13: =INDEX(Items!D$2:D$1032,MATCH($O13,Items!$A$2:$A$1032,0)) -> #N/A
A14: =IF(OR(D14<>D13,D14=""),1,IF(NOT(AND(E14=E13,F14=F13,G14=G13)),A13+1,IF(OR(H14="",AND(H14<>"",H14<>H13,H13<>"")),A13,A13+1))) -> 1 | B14: =IF(D14<>"",TEXT(D14,"YYYYMMDD")&CHAR(64+A14),"") | C14: =IF(OR(B14="",B14<>B13),1,C13+1) -> 1 | F14: =INDEX(Establishment!B$2:B$1005,MATCH($E14,Establishment!$A$2:$A$1005,0)) -> #N/A | G14: =INDEX(Establishment!C$2:C$1005,MATCH($E14,Establishment!$A$2:$A$1005,0)) -> #N/A | M14: =K14*L14 -> 0 | N14: =IF(B14=B13,N13+M14,M14) -> 0 | P14: =INDEX(Items!B$2:B$1032,MATCH($O14,Items!$A$2:$A$1032,0)) -> #N/A | Q14: =INDEX(Items!C$2:C$1032,MATCH($O14,Items!$A$2:$A$1032,0)) -> #N/A | R14: =INDEX(Items!D$2:D$1032,MATCH($O14,Items!$A$2:$A$1032,0)) -> #N/A
A15: =IF(OR(D15<>D14,D15=""),1,IF(NOT(AND(E15=E14,F15=F14,G15=G14)),A14+1,IF(OR(H15="",AND(H15<>"",H15<>H14,H14<>"")),A14,A14+1))) -> 1 | B15: =IF(D15<>"",TEXT(D15,"YYYYMMDD")&CHAR(64+A15),"") | C15: =IF(OR(B15="",B15<>B14),1,C14+1) -> 1 | F15: =INDEX(Establishment!B$2:B$1005,MATCH($E15,Establishment!$A$2:$A$1005,0)) -> #N/A | G15: =INDEX(Establishment!C$2:C$1005,MATCH($E15,Establishment!$A$2:$A$1005,0)) -> #N/A | M15: =K15*L15 -> 0 | N15: =IF(B15=B14,N14+M15,M15) -> 0 | P15: =INDEX(Items!B$2:B$1032,MATCH($O15,Items!$A$2:$A$1032,0)) -> #N/A | Q15: =INDEX(Items!C$2:C$1032,MATCH($O15,Items!$A$2:$A$1032,0)) -> #N/A | R15: =INDEX(Items!D$2:D$1032,MATCH($O15,Items!$A$2:$A$1032,0)) -> #N/A
A16: =IF(OR(D16<>D15,D16=""),1,IF(NOT(AND(E16=E15,F16=F15,G16=G15)),A15+1,IF(OR(H16="",AND(H16<>"",H16<>H15,H15<>"")),A15,A15+1))) -> 1 | B16: =IF(D16<>"",TEXT(D16,"YYYYMMDD")&CHAR(64+A16),"") | C16: =IF(OR(B16="",B16<>B15),1,C15+1) -> 1 | F16: =INDEX(Establishment!B$2:B$1005,MATCH($E16,Establishment!$A$2:$A$1005,0)) -> #N/A | G16: =INDEX(Establishment!C$2:C$1005,MATCH($E16,Establishment!$A$2:$A$1005,0)) -> #N/A | M16: =K16*L16 -> 0 | N16: =IF(B16=B15,N15+M16,M16) -> 0 | P16: =INDEX(Items!B$2:B$1032,MATCH($O16,Items!$A$2:$A$1032,0)) -> #N/A | Q16: =INDEX(Items!C$2:C$1032,MATCH($O16,Items!$A$2:$A$1032,0)) -> #N/A | R16: =INDEX(Items!D$2:D$1032,MATCH($O16,Items!$A$2:$A$1032,0)) -> #N/A
A17: =IF(OR(D17<>D16,D17=""),1,IF(NOT(AND(E17=E16,F17=F16,G17=G16)),A16+1,IF(OR(H17="",AND(H17<>"",H17<>H16,H16<>"")),A16,A16+1))) -> 1 | B17: =IF(D17<>"",TEXT(D17,"YYYYMMDD")&CHAR(64+A17),"") | C17: =IF(OR(B17="",B17<>B16),1,C16+1) -> 1 | F17: =INDEX(Establishment!B$2:B$1005,MATCH($E17,Establishment!$A$2:$A$1005,0)) -> #N/A | G17: =INDEX(Establishment!C$2:C$1005,MATCH($E17,Establishment!$A$2:$A$1005,0)) -> #N/A | M17: =K17*L17 -> 0 | N17: =IF(B17=B16,N16+M17,M17) -> 0 | P17: =INDEX(Items!B$2:B$1032,MATCH($O17,Items!$A$2:$A$1032,0)) -> #N/A | Q17: =INDEX(Items!C$2:C$1032,MATCH($O17,Items!$A$2:$A$1032,0)) -> #N/A | R17: =INDEX(Items!D$2:D$1032,MATCH($O17,Items!$A$2:$A$1032,0)) -> #N/A
A18: =IF(OR(D18<>D17,D18=""),1,IF(NOT(AND(E18=E17,F18=F17,G18=G17)),A17+1,IF(OR(H18="",AND(H18<>"",H18<>H17,H17<>"")),A17,A17+1))) -> 1 | B18: =IF(D18<>"",TEXT(D18,"YYYYMMDD")&CHAR(64+A18),"") | C18: =IF(OR(B18="",B18<>B17),1,C17+1) -> 1 | F18: =INDEX(Establishment!B$2:B$1005,MATCH($E18,Establishment!$A$2:$A$1005,0)) -> #N/A | G18: =INDEX(Establishment!C$2:C$1005,MATCH($E18,Establishment!$A$2:$A$1005,0)) -> #N/A | M18: =K18*L18 -> 0 | N18: =IF(B18=B17,N17+M18,M18) -> 0 | P18: =INDEX(Items!B$2:B$1032,MATCH($O18,Items!$A$2:$A$1032,0)) -> #N/A | Q18: =INDEX(Items!C$2:C$1032,MATCH($O18,Items!$A$2:$A$1032,0)) -> #N/A | R18: =INDEX(Items!D$2:D$1032,MATCH($O18,Items!$A$2:$A$1032,0)) -> #N/A
A19: =IF(OR(D19<>D18,D19=""),1,IF(NOT(AND(E19=E18,F19=F18,G19=G18)),A18+1,IF(OR(H19="",AND(H19<>"",H19<>H18,H18<>"")),A18,A18+1))) -> 1 | B19: =IF(D19<>"",TEXT(D19,"YYYYMMDD")&CHAR(64+A19),"") | C19: =IF(OR(B19="",B19<>B18),1,C18+1) -> 1 | F19: =INDEX(Establishment!B$2:B$1005,MATCH($E19,Establishment!$A$2:$A$1005,0)) -> #N/A | G19: =INDEX(Establishment!C$2:C$1005,MATCH($E19,Establishment!$A$2:$A$1005,0)) -> #N/A | M19: =K19*L19 -> 0 | N19: =IF(B19=B18,N18+M19,M19) -> 0 | P19: =INDEX(Items!B$2:B$1032,MATCH($O19,Items!$A$2:$A$1032,0)) -> #N/A | Q19: =INDEX(Items!C$2:C$1032,MATCH($O19,Items!$A$2:$A$1032,0)) -> #N/A | R19: =INDEX(Items!D$2:D$1032,MATCH($O19,Items!$A$2:$A$1032,0)) -> #N/A
... A25: =IF(OR(D25<>D24,D25=""),1,IF(NOT(AND(E25=E24,F25=F24,G25=G24)),A24+1,IF(OR(H25="",AND(H25<>"",H25<>H24,H24<>"")),A24,A24+1))) -> 1 | B25: =IF(D25<>"",TEXT(D25,"YYYYMMDD")&CHAR(64+A25),"") | C25: =IF(OR(B25="",B25<>B24),1,C24+1) -> 1 | F25: =INDEX(Establishment!B$2:B$1005,MATCH($E25,Establishment!$A$2:$A$1005,0)) -> #N/A | G25: =INDEX(Establishment!C$2:C$1005,MATCH($E25,Establishment!$A$2:$A$1005,0)) -> #N/A | M25: =K25*L25 -> 0 | N25: =IF(B25=B24,N24+M25,M25) -> 0 | P25: =INDEX(Items!B$2:B$1032,MATCH($O25,Items!$A$2:$A$1032,0)) -> #N/A | Q25: =INDEX(Items!C$2:C$1032,MATCH($O25,Items!$A$2:$A$1032,0)) -> #N/A | R25: =INDEX(Items!D$2:D$1032,MATCH($O25,Items!$A$2:$A$1032,0)) -> #N/A
A26: =IF(OR(D26<>D25,D26=""),1,IF(NOT(AND(E26=E25,F26=F25,G26=G25)),A25+1,IF(OR(H26="",AND(H26<>"",H26<>H25,H25<>"")),A25,A25+1))) -> 1 | B26: =IF(D26<>"",TEXT(D26,"YYYYMMDD")&CHAR(64+A26),"") | C26: =IF(OR(B26="",B26<>B25),1,C25+1) -> 1 | F26: Street Vendor | G26: Fried Chicken Seller | M26: =K26*L26 -> 0 | N26: =IF(B26=B25,N25+M26,M26) -> 0 | P26: =INDEX(Items!B$2:B$1032,MATCH($O26,Items!$A$2:$A$1032,0)) -> #N/A | Q26: =INDEX(Items!C$2:C$1032,MATCH($O26,Items!$A$2:$A$1032,0)) -> #N/A | R26: =INDEX(Items!D$2:D$1032,MATCH($O26,Items!$A$2:$A$1032,0)) -> #N/A
A27: =IF(OR(D27<>D26,D27=""),1,IF(NOT(AND(E27=E26,F27=F26,G27=G26)),A26+1,IF(OR(H27="",AND(H27<>"",H27<>H26,H26<>"")),A26,A26+1))) -> 1 | B27: =IF(D27<>"",TEXT(D27,"YYYYMMDD")&CHAR(64+A27),"") | C27: =IF(OR(B27="",B27<>B26),1,C26+1) -> 1 | F27: Street Vendor | G27: Fried Chicken Seller | M27: =K27*L27 -> 0 | N27: =IF(B27=B26,N26+M27,M27) -> 0 | P27: =INDEX(Items!B$2:B$1032,MATCH($O27,Items!$A$2:$A$1032,0)) -> #N/A | Q27: =INDEX(Items!C$2:C$1032,MATCH($O27,Items!$A$2:$A$1032,0)) -> #N/A | R27: =INDEX(Items!D$2:D$1032,MATCH($O27,Items!$A$2:$A$1032,0)) -> #N/A
A28: =IF(OR(D28<>D27,D28=""),1,IF(NOT(AND(E28=E27,F28=F27,G28=G27)),A27+1,IF(OR(H28="",AND(H28<>"",H28<>H27,H27<>"")),A27,A27+1))) -> 1 | B28: =IF(D28<>"",TEXT(D28,"YYYYMMDD")&CHAR(64+A28),"") | C28: =IF(OR(B28="",B28<>B27),1,C27+1) -> 1 | F28: Street Vendor | G28: Fried Chicken Seller | M28: =K28*L28 -> 0 | N28: =IF(B28=B27,N27+M28,M28) -> 0 | P28: =INDEX(Items!B$2:B$1032,MATCH($O28,Items!$A$2:$A$1032,0)) -> #N/A | Q28: =INDEX(Items!C$2:C$1032,MATCH($O28,Items!$A$2:$A$1032,0)) -> #N/A | R28: =INDEX(Items!D$2:D$1032,MATCH($O28,Items!$A$2:$A$1032,0)) -> #N/A
A29: =IF(OR(D29<>D28,D29=""),1,IF(NOT(AND(E29=E28,F29=F28,G29=G28)),A28+1,IF(OR(H29="",AND(H29<>"",H29<>H28,H28<>"")),A28,A28+1))) -> 1 | B29: =IF(D29<>"",TEXT(D29,"YYYYMMDD")&CHAR(64+A29),"") | C29: =IF(OR(B29="",B29<>B28),1,C28+1) -> 1 | F29: =INDEX(Establishment!B$2:B$1005,MATCH($E29,Establishment!$A$2:$A$1005,0)) -> #N/A | G29: =INDEX(Establishment!C$2:C$1005,MATCH($E29,Establishment!$A$2:$A$1005,0)) -> #N/A | M29: =K29*L29 -> 0 | N29: =IF(B29=B28,N28+M29,M29) -> 0 | P29: =INDEX(Items!B$2:B$1032,MATCH($O29,Items!$A$2:$A$1032,0)) -> #N/A | Q29: =INDEX(Items!C$2:C$1032,MATCH($O29,Items!$A$2:$A$1032,0)) -> #N/A | R29: =INDEX(Items!D$2:D$1032,MATCH($O29,Items!$A$2:$A$1032,0)) -> #N/A
A30: =IF(OR(D30<>D29,D30=""),1,IF(NOT(AND(E30=E29,F30=F29,G30=G29)),A29+1,IF(OR(H30="",AND(H30<>"",H30<>H29,H29<>"")),A29,A29+1))) -> 1 | B30: =IF(D30<>"",TEXT(D30,"YYYYMMDD")&CHAR(64+A30),"") | C30: =IF(OR(B30="",B30<>B29),1,C29+1) -> 1 | F30: =INDEX(Establishment!B$2:B$1005,MATCH($E30,Establishment!$A$2:$A$1005,0)) -> #N/A | G30: =INDEX(Establishment!C$2:C$1005,MATCH($E30,Establishment!$A$2:$A$1005,0)) -> #N/A | M30: =K30*L30 -> 0 | N30: =IF(B30=B29,N29+M30,M30) -> 0 | P30: =INDEX(Items!B$2:B$1032,MATCH($O30,Items!$A$2:$A$1032,0)) -> #N/A | Q30: =INDEX(Items!C$2:C$1032,MATCH($O30,Items!$A$2:$A$1032,0)) -> #N/A | R30: =INDEX(Items!D$2:D$1032,MATCH($O30,Items!$A$2:$A$1032,0)) -> #N/A
A31: =IF(OR(D31<>D30,D31=""),1,IF(NOT(AND(E31=E30,F31=F30,G31=G30)),A30+1,IF(OR(H31="",AND(H31<>"",H31<>H30,H30<>"")),A30,A30+1))) -> 1 | B31: =IF(D31<>"",TEXT(D31,"YYYYMMDD")&CHAR(64+A31),"") | C31: =IF(OR(B31="",B31<>B30),1,C30+1) -> 1 | F31: =INDEX(Establishment!B$2:B$1005,MATCH($E31,Establishment!$A$2:$A$1005,0)) -> #N/A | G31: =INDEX(Establishment!C$2:C$1005,MATCH($E31,Establishment!$A$2:$A$1005,0)) -> #N/A | M31: =K31*L31 -> 0 | N31: =IF(B31=B30,N30+M31,M31) -> 0 | P31: =INDEX(Items!B$2:B$1032,MATCH($O31,Items!$A$2:$A$1032,0)) -> #N/A | Q31: =INDEX(Items!C$2:C$1032,MATCH($O31,Items!$A$2:$A$1032,0)) -> #N/A | R31: =INDEX(Items!D$2:D$1032,MATCH($O31,Items!$A$2:$A$1032,0)) -> #N/A
A32: =IF(OR(D32<>D31,D32=""),1,IF(NOT(AND(E32=E31,F32=F31,G32=G31)),A31+1,IF(OR(H32="",AND(H32<>"",H32<>H31,H31<>"")),A31,A31+1))) -> 1 | B32: =IF(D32<>"",TEXT(D32,"YYYYMMDD")&CHAR(64+A32),"") | C32: =IF(OR(B32="",B32<>B31),1,C31+1) -> 1 | F32: Street Vendor | G32: B. Rodriguez | M32: =K32*L32 -> 0 | N32: =IF(B32=B31,N31+M32,M32) -> 0 | P32: =INDEX(Items!B$2:B$1032,MATCH($O32,Items!$A$2:$A$1032,0)) -> #N/A | Q32: =INDEX(Items!C$2:C$1032,MATCH($O32,Items!$A$2:$A$1032,0)) -> #N/A | R32: =INDEX(Items!D$2:D$1032,MATCH($O32,Items!$A$2:$A$1032,0)) -> #N/A
A33: =IF(OR(D33<>D32,D33=""),1,IF(NOT(AND(E33=E32,F33=F32,G33=G32)),A32+1,IF(OR(H33="",AND(H33<>"",H33<>H32,H32<>"")),A32,A32+1))) -> 1 | B33: =IF(D33<>"",TEXT(D33,"YYYYMMDD")&CHAR(64+A33),"") | C33: =IF(OR(B33="",B33<>B32),1,C32+1) -> 1 | F33: Street Vendor | G33: B. Rodriguez | M33: =K33*L33 -> 0 | N33: =IF(B33=B32,N32+M33,M33) -> 0 | P33: =INDEX(Items!B$2:B$1032,MATCH($O33,Items!$A$2:$A$1032,0)) -> #N/A | Q33: =INDEX(Items!C$2:C$1032,MATCH($O33,Items!$A$2:$A$1032,0)) -> #N/A | R33: =INDEX(Items!D$2:D$1032,MATCH($O33,Items!$A$2:$A$1032,0)) -> #N/A
A34: =IF(OR(D34<>D33,D34=""),1,IF(NOT(AND(E34=E33,F34=F33,G34=G33)),A33+1,IF(OR(H34="",AND(H34<>"",H34<>H33,H33<>"")),A33,A33+1))) -> 1 | B34: =IF(D34<>"",TEXT(D34,"YYYYMMDD")&CHAR(64+A34),"") | C34: =IF(OR(B34="",B34<>B33),1,C33+1) -> 1 | F34: Street Vendor | G34: B. Rodriguez | M34: =K34*L34 -> 0 | N34: =IF(B34=B33,N33+M34,M34) -> 0 | P34: =INDEX(Items!B$2:B$1032,MATCH($O34,Items!$A$2:$A$1032,0)) -> #N/A | Q34: =INDEX(Items!C$2:C$1032,MATCH($O34,Items!$A$2:$A$1032,0)) -> #N/A | R34: =INDEX(Items!D$2:D$1032,MATCH($O34,Items!$A$2:$A$1032,0)) -> #N/A
A35: =IF(OR(D35<>D34,D35=""),1,IF(NOT(AND(E35=E34,F35=F34,G35=G34)),A34+1,IF(OR(H35="",AND(H35<>"",H35<>H34,H34<>"")),A34,A34+1))) -> 1 | B35: =IF(D35<>"",TEXT(D35,"YYYYMMDD")&CHAR(64+A35),"") | C35: =IF(OR(B35="",B35<>B34),1,C34+1) -> 1 | F35: Street Vendor | G35: B. Rodriguez | M35: =K35*L35 -> 0 | N35: =IF(B35=B34,N34+M35,M35) -> 0 | P35: =INDEX(Items!B$2:B$1032,MATCH($O35,Items!$A$2:$A$1032,0)) -> #N/A | Q35: =INDEX(Items!C$2:C$1032,MATCH($O35,Items!$A$2:$A$1032,0)) -> #N/A | R35: =INDEX(Items!D$2:D$1032,MATCH($O35,Items!$A$2:$A$1032,0)) -> #N/A
A36: =IF(OR(D36<>D35,D36=""),1,IF(NOT(AND(E36=E35,F36=F35,G36=G35)),A35+1,IF(OR(H36="",AND(H36<>"",H36<>H35,H35<>"")),A35,A35+1))) -> 1 | B36: =IF(D36<>"",TEXT(D36,"YYYYMMDD")&CHAR(64+A36),"") | C36: =IF(OR(B36="",B36<>B35),1,C35+1) -> 1 | F36: Carenderia | G36: B. Rodriguez | M36: =K36*L36 -> 0 | N36: =IF(B36=B35,N35+M36,M36) -> 0 | P36: =INDEX(Items!B$2:B$1032,MATCH($O36,Items!$A$2:$A$1032,0)) -> #N/A | Q36: =INDEX(Items!C$2:C$1032,MATCH($O36,Items!$A$2:$A$1032,0)) -> #N/A | R36: =INDEX(Items!D$2:D$1032,MATCH($O36,Items!$A$2:$A$1032,0)) -> #N/A
A37: =IF(OR(D37<>D36,D37=""),1,IF(NOT(AND(E37=E36,F37=F36,G37=G36)),A36+1,IF(OR(H37="",AND(H37<>"",H37<>H36,H36<>"")),A36,A36+1))) -> 1 | B37: =IF(D37<>"",TEXT(D37,"YYYYMMDD")&CHAR(64+A37),"") | C37: =IF(OR(B37="",B37<>B36),1,C36+1) -> 1 | F37: Carenderia | G37: B. Rodriguez | M37: =K37*L37 -> 0 | N37: =IF(B37=B36,N36+M37,M37) -> 0 | P37: =INDEX(Items!B$2:B$1032,MATCH($O37,Items!$A$2:$A$1032,0)) -> #N/A | Q37: =INDEX(Items!C$2:C$1032,MATCH($O37,Items!$A$2:$A$1032,0)) -> #N/A | R37: =INDEX(Items!D$2:D$1032,MATCH($O37,Items!$A$2:$A$1032,0)) -> #N/A
A38: =IF(OR(D38<>D37,D38=""),1,IF(NOT(AND(E38=E37,F38=F37,G38=G37)),A37+1,IF(OR(H38="",AND(H38<>"",H38<>H37,H37<>"")),A37,A37+1))) -> 1 | B38: =IF(D38<>"",TEXT(D38,"YYYYMMDD")&CHAR(64+A38),"") | C38: =IF(OR(B38="",B38<>B37),1,C37+1) -> 1 | F38: Carenderia | G38: B. Rodriguez | M38: =K38*L38 -> 0 | N38: =IF(B38=B37,N37+M38,M38) -> 0 | P38: =INDEX(Items!B$2:B$1032,MATCH($O38,Items!$A$2:$A$1032,0)) -> #N/A | Q38: =INDEX(Items!C$2:C$1032,MATCH($O38,Items!$A$2:$A$1032,0)) -> #N/A | R38: =INDEX(Items!D$2:D$1032,MATCH($O38,Items!$A$2:$A$1032,0)) -> #N/A
A39: =IF(OR(D39<>D38,D39=""),1,IF(NOT(AND(E39=E38,F39=F38,G39=G38)),A38+1,IF(OR(H39="",AND(H39<>"",H39<>H38,H38<>"")),A38,A38+1))) -> 1 | B39: =IF(D39<>"",TEXT(D39,"YYYYMMDD")&CHAR(64+A39),"") | C39: =IF(OR(B39="",B39<>B38),1,C38+1) -> 1 | F39: Carenderia | G39: B. Rodriguez | M39: =K39*L39 -> 0 | N39: =IF(B39=B38,N38+M39,M39) -> 0 | P39: =INDEX(Items!B$2:B$1032,MATCH($O39,Items!$A$2:$A$1032,0)) -> #N/A | Q39: =INDEX(Items!C$2:C$1032,MATCH($O39,Items!$A$2:$A$1032,0)) -> #N/A | R39: =INDEX(Items!D$2:D$1032,MATCH($O39,Items!$A$2:$A$1032,0)) -> #N/A
A40: =IF(OR(D40<>D39,D40=""),1,IF(NOT(AND(E40=E39,F40=F39,G40=G39)),A39+1,IF(OR(H40="",AND(H40<>"",H40<>H39,H39<>"")),A39,A39+1))) -> 1 | B40: =IF(D40<>"",TEXT(D40,"YYYYMMDD")&CHAR(64+A40),"") | C40: =IF(OR(B40="",B40<>B39),1,C39+1) -> 1 | F40: Carenderia | G40: B. Rodriguez | M40: =K40*L40 -> 0 | N40: =IF(B40=B39,N39+M40,M40) -> 0 | P40: =INDEX(Items!B$2:B$1032,MATCH($O40,Items!$A$2:$A$1032,0)) -> #N/A | Q40: =INDEX(Items!C$2:C$1032,MATCH($O40,Items!$A$2:$A$1032,0)) -> #N/A | R40: =INDEX(Items!D$2:D$1032,MATCH($O40,Items!$A$2:$A$1032,0)) -> #N/A
A41: =IF(OR(D41<>D40,D41=""),1,IF(NOT(AND(E41=E40,F41=F40,G41=G40)),A40+1,IF(OR(H41="",AND(H41<>"",H41<>H40,H40<>"")),A40,A40+1))) -> 1 | B41: =IF(D41<>"",TEXT(D41,"YYYYMMDD")&CHAR(64+A41),"") | C41: =IF(OR(B41="",B41<>B40),1,C40+1) -> 1 | F41: Carenderia | G41: B. Rodriguez | M41: =K41*L41 -> 0 | N41: =IF(B41=B40,N40+M41,M41) -> 0 | P41: =INDEX(Items!B$2:B$1032,MATCH($O41,Items!$A$2:$A$1032,0)) -> #N/A | Q41: =INDEX(Items!C$2:C$1032,MATCH($O41,Items!$A$2:$A$1032,0)) -> #N/A | R41: =INDEX(Items!D$2:D$1032,MATCH($O41,Items!$A$2:$A$1032,0)) -> #N/A
A42: =IF(OR(D42<>D41,D42=""),1,IF(NOT(AND(E42=E41,F42=F41,G42=G41)),A41+1,IF(OR(H42="",AND(H42<>"",H42<>H41,H41<>"")),A41,A41+1))) -> 1 | B42: =IF(D42<>"",TEXT(D42,"YYYYMMDD")&CHAR(64+A42),"") | C42: =IF(OR(B42="",B42<>B41),1,C41+1) -> 1 | F42: Carenderia | G42: B. Rodriguez | M42: =K42*L42 -> 0 | N42: =IF(B42=B41,N41+M42,M42) -> 0 | P42: =INDEX(Items!B$2:B$1032,MATCH($O42,Items!$A$2:$A$1032,0)) -> #N/A | Q42: =INDEX(Items!C$2:C$1032,MATCH($O42,Items!$A$2:$A$1032,0)) -> #N/A | R42: =INDEX(Items!D$2:D$1032,MATCH($O42,Items!$A$2:$A$1032,0)) -> #N/A
